Workbook

Sheet Sheet1
A1: Host Name | B1: #N/A
A2: BLRSBMUATVAPT | B2: 100.112.5.101
A3: BNG-MHS-SBM-FW01 | B3: 100.112.0.163
A4: BNG-SBM-MHS-EXT-FGT-FW01 | B4: 100.112.5.129
A5: MUM-MHS-SBM-FW01 | B5: 100.121.16.65
A6: MUM-MHS-SBM-FW02 | B6: 100.121.16.66
A7: BKC-SBM-MHS-EXT-FGT-FW01 \ FW02 | B7: 100.121.17.65
A8: BLRSBMUATFINAPP_OLD | B8: 100.112.4.151
A9: BLRSBMUATMADP | B9: 100.112.4.217
A10: BLRSBMUATFASAPP | B10: 100.112.4.49
A11: BLRSBMUATFINWEB_OLD | B11: 100.112.5.50
A12: BANSBMUATFINJBOSS | B12: 100.112.5.80
A13: BANSBMUATFINAPP | B13: 100.112.5.81
... A61: BLRSBMWEB2 | B61: 100.112.5.20
A62: BLRSBMUATWEB | B62: 100.112.5.99 | C62: 100.121.17.22
A63: MUMSBMFINWEB1 | B63: 100.121.17.16
A64: MUMSBMFINWEB2 | B64: 100.121.17.17
A65: MUMSBMFINJBOSS1 | B65: 100.121.16.213
A66: MUMSBMFINJBOSS2 | B66: 100.121.16.214 | C66: 100.121.17.6
A67: MUMSBMFINAPP1 | B67: 100.121.16.149
A68: MUMSBMFINAPP2 | B68: 100.121.16.150 | C68: 100.121.16.198 | D68: 100.121.16.134
A69: BLRSBMUATFINWEB | B69: 100.112.5.48
A70: BLRSBMUATFINJBOSS | B70: 100.112.4.213
A71: BLRSBMUATFINAPP | B71: 100.112.4.149
A72: BANSBMUATFINDB | B72: 100.112.4.73
A73: BLRSBMUATFINDB1 | B73: 100.112.4.79
A74: BLRSBMFINJBOSS | B74: 100.112.1.149 | C74: 100.112.1.70
A75: BLRSBMFINJBOSS1 | B75: 100.112.1.23
A76: BLRSBMFINAPP | B76: 100.112.1.85
A77: BLRSBMFINAPP1 | B77: 100.112.1.5
A78: BLRSBMFINAPP2 | B78: 100.112.1.87
A79: BLRSBMFINWEB | B79: 100.112.1.207
A80: BLRSBMFINWEB1 | B80: 100.112.0.233
A81: BLRSBMFINDB | B81: 100.112.0.78
A82: MUMSBMTREASAPP2 | B82: 100.121.16.215
A83: MUMSBMTREASAPP1 | B83: 100.121.16.216
A84: BLRSBMTREASAPP | B84: 100.112.1.150
A85: BLRSBMUATTREASAPP | B85: 100.112.4.214
A86: BLRSBMUATTREASDB1 | B86: 100.112.4.98
... A94: MUMSBRIBWEB1 | B94: 100.121.17.76
...

Sheet DR
A1: VLAN | B1: IP Address | C1: Hostname | D1: VLAN | E1: IP Address | F1: Hostname | G1: VLAN | H1: IP Address | I1: Hostname | J1: VLAN | K1: IP Address | L1: Hostname | M1: VLAN | N1: IP Address | O1: Hostname | P1: VLAN | Q1: IP Address | R1: Hostname | S1: VLAN | T1: IP Address | U1: Hostname | V1: VLAN | W1: IP Address | X1: Hostname | Y1: VLAN | Z1: IP Address | AA1: Hostname | AB1: VLAN | AC1: IP Address | AD1: Hostname | AE1: VLAN | AF1: IP Address | AG1: Hostname | AH1: VLAN | AI1: IP Address | AJ1: Hostname | AK1: VLAN | AL1: IP Address | AM1: Hostname | AN1: VLAN | AO1: IP Address | AP1: Hostname
B2: 100.112.0.1 | C2: =_xlfn.XLOOKUP(B2,Sheet1!B:B,Sheet1!A:A) -> #N/A | D2: 860 APP | E2: 100.112.1.1 | F2: =_xlfn.XLOOKUP(E2,Sheet1!B:B,Sheet1!A:A) -> #N/A | H2: 100.112.2.1 | I2: =_xlfn.XLOOKUP(H2,Sheet1!B:B,Sheet1!A:A) -> #N/A | J2: NAT_SUB 916 | K2: 100.112.3.1 | L2: =_xlfn.XLOOKUP(K2,Sheet1!B:B,Sheet1!A:A) -> #N/A | N2: 100.112.4.1 | O2: =_xlfn.XLOOKUP(N2,Sheet1!B:B,Sheet1!A:A) -> #N/A | P2: 867 UAT_WEB_WEB-E | Q2: 100.112.5.1 | R2: =_xlfn.XLOOKUP(Q2,Sheet1!B:B,Sheet1!A:A) -> #N/A | T2: 100.112.6.1 | U2: =_xlfn.XLOOKUP(T2,Sheet1!B:B,Sheet1!A:A) -> #N/A | V2: 912 UAT_APP2 | W2: 100.112.7.1 | X2: =_xlfn.XLOOKUP(W2,Sheet1!A:A,Sheet1!B:B) -> #N/A | Y2: 906 VDI-APP | Z2: 100.112.9.1 | AA2: =_xlfn.XLOOKUP(Z2,Sheet1!B:B,Sheet1!A:A) -> #N/A | AB2: 909 VDI | AC2: 100.112.10.1 | AD2: =_xlfn.XLOOKUP(AC2,Sheet1!B:B,Sheet1!A:A) -> #N/A | AE2: 670 New_APP | AF2: 100.112.12.1 | AG2: =_xlfn.XLOOKUP(AF2,Sheet1!B:B,Sheet1!A:A) -> #N/A | AH2: 902 Server_Proxy | AI2: 100.112.26.1 | AJ2: =_xlfn.XLOOKUP(AI2,Sheet1!B:B,Sheet1!A:A) -> #N/A | AK2: 903 Proxy_to_Int | AL2: 100.112.27.1 | AM2: =_xlfn.XLOOKUP(AL2,Sheet1!B:B,Sheet1!A:A) -> #N/A | AN2: 917 DSD | AO2: 100.112.28.1 | AP2: =_xlfn.XLOOKUP(AO2,Sheet1!B:B,Sheet1!A:A) -> DR_ASA Firewall1
B3: 100.112.0.2 | C3: =_xlfn.XLOOKUP(B3,Sheet1!B:B,Sheet1!A:A) -> #N/A | E3: 100.112.1.2 | F3: =_xlfn.XLOOKUP(E3,Sheet1!B:B,Sheet1!A:A) -> BLRSBMVMS01 | H3: 100.112.2.2 | I3: =_xlfn.XLOOKUP(H3,Sheet1!B:B,Sheet1!A:A) -> #N/A | J3: NAT_SUB 916 | K3: 100.112.3.2 | L3: =_xlfn.XLOOKUP(K3,Sheet1!B:B,Sheet1!A:A) -> #N/A | N3: 100.112.4.2 | O3: =_xlfn.XLOOKUP(N3,Sheet1!B:B,Sheet1!A:A) -> #N/A | P3: 867 UAT_WEB_WEB-E | Q3: 100.112.5.2 | R3: =_xlfn.XLOOKUP(Q3,Sheet1!B:B,Sheet1!A:A) -> #N/A | T3: 100.112.6.2 | U3: =_xlfn.XLOOKUP(T3,Sheet1!B:B,Sheet1!A:A) -> #N/A | V3: 912 UAT_APP2 | W3: 100.112.7.2 | X3: =_xlfn.XLOOKUP(W3,Sheet1!B:B,Sheet1!A:A) -> LB Clustering self IP(standby) | Y3: 906 VDI-APP | Z3: 100.112.9.2 | AA3: =_xlfn.XLOOKUP(Z3,Sheet1!B:B,Sheet1!A:A) -> BLRSBMVDIHCS01 | AB3: 909 VDI | AC3: 100.112.10.2 | AD3: =_xlfn.XLOOKUP(AC3,Sheet1!B:B,Sheet1!A:A) -> #N/A | AE3: 670 New_APP | AF3: 100.112.12.2 | AG3: =_xlfn.XLOOKUP(AF3,Sheet1!B:B,Sheet1!A:A) -> BLRSBMSWIFTAPP | AH3: 902 Server_Proxy | AI3: 100.112.26.2 | AJ3: =_xlfn.XLOOKUP(AI3,Sheet1!B:B,Sheet1!A:A) -> #N/A | AK3: 903 Proxy_to_Int | AL3: 100.112.27.2 | AM3: =_xlfn.XLOOKUP(AL3,Sheet1!B:B,Sheet1!A:A) -> #N/A | AN3: 917 DSD | AO3: 100.112.28.2 | AP3: =_xlfn.XLOOKUP(AO3,Sheet1!B:B,Sheet1!A:A) -> DR_ASA Firewall2
B4: 100.112.0.3 | C4: =_xlfn.XLOOKUP(B4,Sheet1!B:B,Sheet1!A:A) -> #N/A | E4: 100.112.1.3 | F4: =_xlfn.XLOOKUP(E4,Sheet1!B:B,Sheet1!A:A) -> #N/A | H4: 100.112.2.3 | I4: =_xlfn.XLOOKUP(H4,Sheet1!B:B,Sheet1!A:A) -> #N/A | J4: NAT_SUB 916 | K4: 100.112.3.3 | L4: =_xlfn.XLOOKUP(K4,Sheet1!B:B,Sheet1!A:A) -> #N/A | N4: 100.112.4.3 | O4: =_xlfn.XLOOKUP(N4,Sheet1!B:B,Sheet1!A:A) -> #N/A | P4: 867 UAT_WEB_WEB-E | Q4: 100.112.5.3 | R4: =_xlfn.XLOOKUP(Q4,Sheet1!B:B,Sheet1!A:A) -> NESL VIDEO KYC VIP | T4: 100.112.6.3 | U4: =_xlfn.XLOOKUP(T4,Sheet1!B:B,Sheet1!A:A) -> #N/A | V4: 912 UAT_APP2 | W4: 100.112.7.3 | X4: =_xlfn.XLOOKUP(W4,Sheet1!B:B,Sheet1!A:A) -> LB Clustering self IP(floating) | Y4: 906 VDI-APP | Z4: 100.112.9.3 | AA4: =_xlfn.XLOOKUP(Z4,Sheet1!B:B,Sheet1!A:A) -> BLRSBMVDIDEM01 | AB4: 909 VDI | AC4: 100.112.10.3 | AD4: =_xlfn.XLOOKUP(AC4,Sheet1!B:B,Sheet1!A:A) -> #N/A | AE4: 670 New_APP | AF4: 100.112.12.3 | AG4: =_xlfn.XLOOKUP(AF4,Sheet1!B:B,Sheet1!A:A) -> ASA VLAN Standby | AH4: 902 Server_Proxy | AI4: 100.112.26.3 | AJ4: =_xlfn.XLOOKUP(AI4,Sheet1!B:B,Sheet1!A:A) -> #N/A | AK4: 903 Proxy_to_Int | AL4: 100.112.27.3 | AM4: =_xlfn.XLOOKUP(AL4,Sheet1!B:B,Sheet1!A:A) -> #N/A | AN4: 917 DSD | AO4: 100.112.28.3 | AP4: =_xlfn.XLOOKUP(AO4,Sheet1!B:B,Sheet1!A:A) -> BLRSBMPROSW05
B5: 100.112.0.4 | C5: =_xlfn.XLOOKUP(B5,Sheet1!B:B,Sheet1!A:A) -> #N/A | E5: 100.112.1.4 | F5: =_xlfn.XLOOKUP(E5,Sheet1!B:B,Sheet1!A:A) -> BLRSBMDMSAPP1 | H5: 100.112.2.4 | I5: =_xlfn.XLOOKUP(H5,Sheet1!B:B,Sheet1!A:A) -> #N/A | J5: NAT_SUB 916 | K5: 100.112.3.4 | L5: =_xlfn.XLOOKUP(K5,Sheet1!B:B,Sheet1!A:A) -> #N/A | N5: 100.112.4.4 | O5: =_xlfn.XLOOKUP(N5,Sheet1!B:B,Sheet1!A:A) -> #N/A | P5: 867 UAT_WEB_WEB-E | Q5: 100.112.5.4 | R5: =_xlfn.XLOOKUP(Q5,Sheet1!B:B,Sheet1!A:A) -> #N/A | T5: 100.112.6.4 | U5: =_xlfn.XLOOKUP(T5,Sheet1!B:B,Sheet1!A:A) -> #N/A | V5: 912 UAT_APP2 | W5: 100.112.7.4 | X5: =_xlfn.XLOOKUP(W5,Sheet1!B:B,Sheet1!A:A) -> Reserved for Acalvio | Y5: 906 VDI-APP | Z5: 100.112.9.4 | AA5: =_xlfn.XLOOKUP(Z5,Sheet1!B:B,Sheet1!A:A) -> BLRSBMVDIEDGW01 | AB5: 909 VDI | AC5: 100.112.10.4 | AD5: =_xlfn.XLOOKUP(AC5,Sheet1!B:B,Sheet1!A:A) -> #N/A | AE5: 670 New_APP | AF5: 100.112.12.4 | AG5: =_xlfn.XLOOKUP(AF5,Sheet1!B:B,Sheet1!A:A) -> ASA VLAN Standby | AH5: 902 Server_Proxy | AI5: 100.112.26.4 | AJ5: =_xlfn.XLOOKUP(AI5,Sheet1!B:B,Sheet1!A:A) -> #N/A | AK5: 903 Proxy_to_Int | AL5: 100.112.27.4 | AM5: =_xlfn.XLOOKUP(AL5,Sheet1!B:B,Sheet1!A:A) -> BLRSBMNSPROXY1 | AN5: 917 DSD | AO5: 100.112.28.4 | AP5: =_xlfn.XLOOKUP(AO5,Sheet1!B:B,Sheet1!A:A) -> BLRSBMPROSW06
B6: 100.112.0.5 | C6: =_xlfn.XLOOKUP(B6,Sheet1!B:B,Sheet1!A:A) -> #N/A | E6: 100.112.1.5 | F6: =_xlfn.XLOOKUP(E6,Sheet1!B:B,Sheet1!A:A) -> BLRSBMFINAPP1 | H6: 100.112.2.5 | I6: =_xlfn.XLOOKUP(H6,Sheet1!B:B,Sheet1!A:A) -> #N/A | J6: NAT_SUB 916 | K6: 100.112.3.5 | L6: =_xlfn.XLOOKUP(K6,Sheet1!B:B,Sheet1!A:A) -> #N/A | N6: 100.112.4.5 | O6: =_xlfn.XLOOKUP(N6,Sheet1!B:B,Sheet1!A:A) -> #N/A | P6: 867 UAT_WEB_WEB-E | Q6: 100.112.5.5 | R6: =_xlfn.XLOOKUP(Q6,Sheet1!B:B,Sheet1!A:A) -> #N/A | T6: 100.112.6.5 | U6: =_xlfn.XLOOKUP(T6,Sheet1!B:B,Sheet1!A:A) -> #N/A | V6: 912 UAT_APP2 | W6: 100.112.7.5 | X6: =_xlfn.XLOOKUP(W6,Sheet1!B:B,Sheet1!A:A) -> Reserved for Acalvio | Y6: 906 VDI-APP | Z6: 100.112.9.5 | AA6: =_xlfn.XLOOKUP(Z6,Sheet1!B:B,Sheet1!A:A) -> #N/A | AB6: 909 VDI | AC6: 100.112.10.5 | AD6: =_xlfn.XLOOKUP(AC6,Sheet1!B:B,Sheet1!A:A) -> #N/A | AE6: 670 New_APP | AF6: 100.112.12.5 | AG6: =_xlfn.XLOOKUP(AF6,Sheet1!B:B,Sheet1!A:A) -> BLRSBMSWFTJUMP | AH6: 902 Server_Proxy | AI6: 100.112.26.5 | AJ6: =_xlfn.XLOOKUP(AI6,Sheet1!B:B,Sheet1!A:A) -> #N/A | AK6: 903 Proxy_to_Int | AL6: 100.112.27.5 | AM6: =_xlfn.XLOOKUP(AL6,Sheet1!B:B,Sheet1!A:A) -> #N/A | AN6: 917 DSD | AO6: 100.112.28.5 | AP6: =_xlfn.XLOOKUP(AO6,Sheet1!B:B,Sheet1!A:A) -> BLRSBMFORTIMGR
B7: 100.112.0.6 | C7: =_xlfn.XLOOKUP(B7,Sheet1!B:B,Sheet1!A:A) -> #N/A | E7: 100.112.1.6 | F7: =_xlfn.XLOOKUP(E7,Sheet1!B:B,Sheet1!A:A) -> BLRSBMDLPMGT | H7: 100.112.2.6 | I7: =_xlfn.XLOOKUP(H7,Sheet1!B:B,Sheet1!A:A) -> #N/A | J7: NAT_SUB 916 | K7: 100.112.3.6 | L7: =_xlfn.XLOOKUP(K7,Sheet1!B:B,Sheet1!A:A) -> #N/A | N7: 100.112.4.6 | O7: =_xlfn.XLOOKUP(N7,Sheet1!B:B,Sheet1!A:A) -> #N/A | P7: 867 UAT_WEB_WEB-E | Q7: 100.112.5.6 | R7: =_xlfn.XLOOKUP(Q7,Sheet1!B:B,Sheet1!A:A) -> #N/A | T7: 100.112.6.6 | U7: =_xlfn.XLOOKUP(T7,Sheet1!B:B,Sheet1!A:A) -> #N/A | V7: 912 UAT_APP2 | W7: 100.112.7.6 | X7: =_xlfn.XLOOKUP(W7,Sheet1!B:B,Sheet1!A:A) -> Reserved for Acalvio | Y7: 906 VDI-APP | Z7: 100.112.9.6 | AA7: =_xlfn.XLOOKUP(Z7,Sheet1!B:B,Sheet1!A:A) -> #N/A | AB7: 909 VDI | AC7: 100.112.10.6 | AD7: =_xlfn.XLOOKUP(AC7,Sheet1!B:B,Sheet1!A:A) -> #N/A | AE7: 670 New_APP | AF7: 100.112.12.6 | AG7: =_xlfn.XLOOKUP(AF7,Sheet1!B:B,Sheet1!A:A) -> BLRSBMSWIFT02 | AH7: 902 Server_Proxy | AI7: 100.112.26.6 | AJ7: =_xlfn.XLOOKUP(AI7,Sheet1!B:B,Sheet1!A:A) -> #N/A | AK7: 903 Proxy_to_Int | AL7: 100.112.27.6 | AM7: =_xlfn.XLOOKUP(AL7,Sheet1!B:B,Sheet1!A:A) -> #N/A | AN7: 917 DSD | AO7: 100.112.28.6 | AP7: =_xlfn.XLOOKUP(AO7,Sheet1!B:B,Sheet1!A:A) -> #N/A
B8: 100.112.0.7 | C8: =_xlfn.XLOOKUP(B8,Sheet1!B:B,Sheet1!A:A) -> #N/A | E8: 100.112.1.7 | F8: =_xlfn.XLOOKUP(E8,Sheet1!B:B,Sheet1!A:A) -> BLRSBMDLPOCR | H8: 100.112.2.7 | I8: =_xlfn.XLOOKUP(H8,Sheet1!B:B,Sheet1!A:A) -> #N/A | J8: NAT_SUB 916 | K8: 100.112.3.7 | L8: =_xlfn.XLOOKUP(K8,Sheet1!B:B,Sheet1!A:A) -> #N/A | N8: 100.112.4.7 | O8: =_xlfn.XLOOKUP(N8,Sheet1!B:B,Sheet1!A:A) -> #N/A | P8: 867 UAT_WEB_WEB-E | Q8: 100.112.5.7 | R8: =_xlfn.XLOOKUP(Q8,Sheet1!B:B,Sheet1!A:A) -> #N/A | T8: 100.112.6.7 | U8: =_xlfn.XLOOKUP(T8,Sheet1!B:B,Sheet1!A:A) -> #N/A | V8: 912 UAT_APP2 | W8: 100.112.7.7 | X8: =_xlfn.XLOOKUP(W8,Sheet1!B:B,Sheet1!A:A) -> BLRSBMUATRDLAPP01 | Y8: 906 VDI-APP | Z8: 100.112.9.7 | AA8: =_xlfn.XLOOKUP(Z8,Sheet1!B:B,Sheet1!A:A) -> #N/A | AB8: 909 VDI | AC8: 100.112.10.7 | AD8: =_xlfn.XLOOKUP(AC8,Sheet1!B:B,Sheet1!A:A) -> #N/A | AE8: 670 New_APP | AF8: 100.112.12.7 | AG8: =_xlfn.XLOOKUP(AF8,Sheet1!B:B,Sheet1!A:A) -> BLRSBMSWIFT03 | AH8: 902 Server_Proxy | AI8: 100.112.26.7 | AJ8: =_xlfn.XLOOKUP(AI8,Sheet1!B:B,Sheet1!A:A) -> BLRSBMGUARDICORE | AK8: 903 Proxy_to_Int | AL8: 100.112.27.7 | AM8: =_xlfn.XLOOKUP(AL8,Sheet1!B:B,Sheet1!A:A) -> #N/A | AN8: 917 DSD | AO8: 100.112.28.7 | AP8: =_xlfn.XLOOKUP(AO8,Sheet1!B:B,Sheet1!A:A) -> #N/A
B9: 100.112.0.8 | C9: =_xlfn.XLOOKUP(B9,Sheet1!B:B,Sheet1!A:A) -> #N/A | E9: 100.112.1.8 | F9: =_xlfn.XLOOKUP(E9,Sheet1!B:B,Sheet1!A:A) -> BLRSBMD2KAPP | H9: 100.112.2.8 | I9: =_xlfn.XLOOKUP(H9,Sheet1!B:B,Sheet1!A:A) -> #N/A | J9: NAT_SUB 916 | K9: 100.112.3.8 | L9: =_xlfn.XLOOKUP(K9,Sheet1!B:B,Sheet1!A:A) -> #N/A | N9: 100.112.4.8 | O9: =_xlfn.XLOOKUP(N9,Sheet1!B:B,Sheet1!A:A) -> #N/A | P9: 867 UAT_WEB_WEB-E | Q9: 100.112.5.8 | R9: =_xlfn.XLOOKUP(Q9,Sheet1!B:B,Sheet1!A:A) -> #N/A | T9: 100.112.6.8 | U9: =_xlfn.XLOOKUP(T9,Sheet1!B:B,Sheet1!A:A) -> #N/A | V9: 912 UAT_APP2 | W9: 100.112.7.8 | X9: =_xlfn.XLOOKUP(W9,Sheet1!B:B,Sheet1!A:A) -> BLRSBMUATBMLAPP01 | Y9: 906 VDI-APP | Z9: 100.112.9.8 | AA9: =_xlfn.XLOOKUP(Z9,Sheet1!B:B,Sheet1!A:A) -> #N/A | AB9: 909 VDI | AC9: 100.112.10.8 | AD9: =_xlfn.XLOOKUP(AC9,Sheet1!B:B,Sheet1!A:A) -> #N/A | AE9: 670 New_APP | AF9: 100.112.12.8 | AG9: =_xlfn.XLOOKUP(AF9,Sheet1!B:B,Sheet1!A:A) -> BLRSBMSWTICAPP | AH9: 902 Server_Proxy | AI9: 100.112.26.8 | AJ9: =_xlfn.XLOOKUP(AI9,Sheet1!B:B,Sheet1!A:A) -> #N/A | AK9: 903 Proxy_to_Int | AL9: 100.112.27.8 | AM9: =_xlfn.XLOOKUP(AL9,Sheet1!B:B,Sheet1!A:A) -> #N/A | AN9: 917 DSD | AO9: 100.112.28.8 | AP9: =_xlfn.XLOOKUP(AO9,Sheet1!B:B,Sheet1!A:A) -> #N/A
B10: 100.112.0.9 | C10: =_xlfn.XLOOKUP(B10,Sheet1!B:B,Sheet1!A:A) -> #N/A | E10: 100.112.1.9 | F10: =_xlfn.XLOOKUP(E10,Sheet1!B:B,Sheet1!A:A) -> BLRSBMD2KREP | H10: 100.112.2.9 | I10: =_xlfn.XLOOKUP(H10,Sheet1!B:B,Sheet1!A:A) -> #N/A | J10: NAT_SUB 916 | K10: 100.112.3.9 | L10: =_xlfn.XLOOKUP(K10,Sheet1!B:B,Sheet1!A:A) -> #N/A | N10: 100.112.4.9 | O10: =_xlfn.XLOOKUP(N10,Sheet1!B:B,Sheet1!A:A) -> #N/A | P10: 867 UAT_WEB_WEB-E | Q10: 100.112.5.9 | R10: =_xlfn.XLOOKUP(Q10,Sheet1!B:B,Sheet1!A:A) -> #N/A | T10: 100.112.6.9 | U10: =_xlfn.XLOOKUP(T10,Sheet1!B:B,Sheet1!A:A) -> #N/A | V10: 912 UAT_APP2 | W10: 100.112.7.9 | X10: =_xlfn.XLOOKUP(W10,Sheet1!B:B,Sheet1!A:A) -> BLRSBMUATRDLAPP02 | Y10: 906 VDI-APP | Z10: 100.112.9.9 | AA10: =_xlfn.XLOOKUP(Z10,Sheet1!B:B,Sheet1!A:A) -> #N/A | AB10: 909 VDI | AC10: 100.112.10.9 | AD10: =_xlfn.XLOOKUP(AC10,Sheet1!B:B,Sheet1!A:A) -> #N/A | AE10: 670 New_APP | AF10: 100.112.12.9 | AG10: =_xlfn.XLOOKUP(AF10,Sheet1!B:B,Sheet1!A:A) -> BLRSBMSWTICDB | AH10: 902 Server_Proxy | AI10: 100.112.26.9 | AJ10: =_xlfn.XLOOKUP(AI10,Sheet1!B:B,Sheet1!A:A) -> #N/A | AK10: 903 Proxy_to_Int | AL10: 100.112.27.9 | AM10: =_xlfn.XLOOKUP(AL10,Sheet1!B:B,Sheet1!A:A) -> #N/A | AN10: 917 DSD | AO10: 100.112.28.9 | AP10: =_xlfn.XLOOKUP(AO10,Sheet1!B:B,Sheet1!A:A) -> #N/A
B11: 100.112.0.10 | C11: =_xlfn.XLOOKUP(B11,Sheet1!B:B,Sheet1!A:A) -> #N/A | E11: 100.112.1.10 | F11: =_xlfn.XLOOKUP(E11,Sheet1!B:B,Sheet1!A:A) -> BLRSBMDYNAAPP | H11: 100.112.2.10 | I11: =_xlfn.XLOOKUP(H11,Sheet1!B:B,Sheet1!A:A) -> #N/A | J11: NAT_SUB 916 | K11: 100.112.3.10 | L11: =_xlfn.XLOOKUP(K11,Sheet1!B:B,Sheet1!A:A) -> 59.164.69.241 | N11: 100.112.4.10 | O11: =_xlfn.XLOOKUP(N11,Sheet1!B:B,Sheet1!A:A) -> #N/A | P11: 867 UAT_WEB_WEB-E | Q11: 100.112.5.10 | R11: =_xlfn.XLOOKUP(Q11,Sheet1!B:B,Sheet1!A:A) -> #N/A | T11: 100.112.6.10 | U11: =_xlfn.XLOOKUP(T11,Sheet1!B:B,Sheet1!A:A) -> #N/A | V11: 912 UAT_APP2 | W11: 100.112.7.10 | X11: =_xlfn.XLOOKUP(W11,Sheet1!B:B,Sheet1!A:A) -> Firewall temporary | Y11: 906 VDI-APP | Z11: 100.112.9.10 | AA11: =_xlfn.XLOOKUP(Z11,Sheet1!B:B,Sheet1!A:A) -> #N/A | AB11: 909 VDI | AC11: 100.112.10.10 | AD11: =_xlfn.XLOOKUP(AC11,Sheet1!B:B,Sheet1!A:A) -> BLRSBMRDSH01 | AE11: 670 New_APP | AF11: 100.112.12.10 | AG11: =_xlfn.XLOOKUP(AF11,Sheet1!B:B,Sheet1!A:A) -> #N/A | AH11: 902 Server_Proxy | AI11: 100.112.26.10 | AJ11: =_xlfn.XLOOKUP(AI11,Sheet1!B:B,Sheet1!A:A) -> #N/A | AK11: 903 Proxy_to_Int | AL11: 100.112.27.10 | AM11: =_xlfn.XLOOKUP(AL11,Sheet1!B:B,Sheet1!A:A) -> #N/A | AN11: 917 DSD | AO11: 100.112.28.10 | AP11: =_xlfn.XLOOKUP(AO11,Sheet1!B:B,Sheet1!A:A) -> #N/A
B12: 100.112.0.11 | C12: =_xlfn.XLOOKUP(B12,Sheet1!B:B,Sheet1!A:A) -> #N/A | E12: 100.112.1.11 | F12: =_xlfn.XLOOKUP(E12,Sheet1!B:B,Sheet1!A:A) -> BLRSBMGETV01 | H12: 100.112.2.11 | I12: =_xlfn.XLOOKUP(H12,Sheet1!B:B,Sheet1!A:A) -> #N/A | J12: NAT_SUB 916 | K12: 100.112.3.11 | L12: =_xlfn.XLOOKUP(K12,Sheet1!B:B,Sheet1!A:A) -> #N/A | N12: 100.112.4.11 | O12: =_xlfn.XLOOKUP(N12,Sheet1!B:B,Sheet1!A:A) -> #N/A | P12: 867 UAT_WEB_WEB-E | Q12: 100.112.5.11 | R12: =_xlfn.XLOOKUP(Q12,Sheet1!B:B,Sheet1!A:A) -> #N/A | T12: 100.112.6.11 | U12: =_xlfn.XLOOKUP(T12,Sheet1!B:B,Sheet1!A:A) -> #N/A | V12: 912 UAT_APP2 | W12: 100.112.7.11 | X12: =_xlfn.XLOOKUP(W12,Sheet1!B:B,Sheet1!A:A) -> BLRSBMUTLNSAPP | Y12: 906 VDI-APP | Z12: 100.112.9.11 | AA12: =_xlfn.XLOOKUP(Z12,Sheet1!B:B,Sheet1!A:A) -> #N/A | AB12: 909 VDI | AC12: 100.112.10.11 | AD12: =_xlfn.XLOOKUP(AC12,Sheet1!B:B,Sheet1!A:A) -> BLRSBMRDSH02 | AE12: 670 New_APP | AF12: 100.112.12.11 | AG12: =_xlfn.XLOOKUP(AF12,Sheet1!B:B,Sheet1!A:A) -> #N/A | AH12: 902 Server_Proxy | AI12: 100.112.26.11 | AJ12: =_xlfn.XLOOKUP(AI12,Sheet1!B:B,Sheet1!A:A) -> #N/A | AK12: 903 Proxy_to_Int | AL12: 100.112.27.11 | AM12: =_xlfn.XLOOKUP(AL12,Sheet1!B:B,Sheet1!A:A) -> #N/A | AN12: 917 DSD | AO12: 100.112.28.11 | AP12: =_xlfn.XLOOKUP(AO12,Sheet1!B:B,Sheet1!A:A) -> #N/A
B13: 100.112.0.12 | C13: =_xlfn.XLOOKUP(B13,Sheet1!B:B,Sheet1!A:A) -> #N/A | E13: 100.112.1.12 | F13: =_xlfn.XLOOKUP(E13,Sheet1!B:B,Sheet1!A:A) -> BLRSBNESLAPP1 | H13: 100.112.2.12 | I13: =_xlfn.XLOOKUP(H13,Sheet1!B:B,Sheet1!A:A) -> #N/A | J13: NAT_SUB 916 | K13: 100.112.3.12 | L13: =_xlfn.XLOOKUP(K13,Sheet1!B:B,Sheet1!A:A) -> #N/A | N13: 100.112.4.12 | O13: =_xlfn.XLOOKUP(N13,Sheet1!B:B,Sheet1!A:A) -> #N/A | P13: 867 UAT_WEB_WEB-E | Q13: 100.112.5.12 | R13: =_xlfn.XLOOKUP(Q13,Sheet1!B:B,Sheet1!A:A) -> #N/A | T13: 100.112.6.12 | U13: =_xlfn.XLOOKUP(T13,Sheet1!B:B,Sheet1!A:A) -> #N/A | V13: 912 UAT_APP2 | W13: 100.112.7.12 | X13: =_xlfn.XLOOKUP(W13,Sheet1!B:B,Sheet1!A:A) -> BLRSBMUTSWFJMP | Y13: 906 VDI-APP | Z13: 100.112.9.12 | AA13: =_xlfn.XLOOKUP(Z13,Sheet1!B:B,Sheet1!A:A) -> #N/A | AB13: 909 VDI | AC13: 100.112.10.12 | AD13: =_xlfn.XLOOKUP(AC13,Sheet1!B:B,Sheet1!A:A) -> BLRSBMRDSH03 | AE13: 670 New_APP | AF13: 100.112.12.12 | AG13: =_xlfn.XLOOKUP(AF13,Sheet1!B:B,Sheet1!A:A) -> #N/A | AH13: 902 Server_Proxy | AI13: 100.112.26.12 | AJ13: =_xlfn.XLOOKUP(AI13,Sheet1!B:B,Sheet1!A:A) -> #N/A | AK13: 903 Proxy_to_Int | AL13: 100.112.27.12 | AM13: =_xlfn.XLOOKUP(AL13,Sheet1!B:B,Sheet1!A:A) -> #N/A | AN13: 917 DSD | AO13: 100.112.28.12 | AP13: =_xlfn.XLOOKUP(AO13,Sheet1!B:B,Sheet1!A:A) -> #N/A
B14: 100.112.0.13 | C14: =_xlfn.XLOOKUP(B14,Sheet1!B:B,Sheet1!A:A) -> #N/A | E14: 100.112.1.13 | F14: =_xlfn.XLOOKUP(E14,Sheet1!B:B,Sheet1!A:A) -> BLRSBMFTPAPP1 | H14: 100.112.2.13 | I14: =_xlfn.XLOOKUP(H14,Sheet1!B:B,Sheet1!A:A) -> #N/A | J14: NAT_SUB 916 | K14: 100.112.3.13 | L14: =_xlfn.XLOOKUP(K14,Sheet1!B:B,Sheet1!A:A) -> #N/A | N14: 100.112.4.13 | O14: =_xlfn.XLOOKUP(N14,Sheet1!B:B,Sheet1!A:A) -> #N/A | P14: 867 UAT_WEB_WEB-E | Q14: 100.112.5.13 | R14: =_xlfn.XLOOKUP(Q14,Sheet1!B:B,Sheet1!A:A) -> #N/A | T14: 100.112.6.13 | U14: =_xlfn.XLOOKUP(T14,Sheet1!B:B,Sheet1!A:A) -> #N/A | V14: 912 UAT_APP2 | W14: 100.112.7.13 | X14: =_xlfn.XLOOKUP(W14,Sheet1!B:B,Sheet1!A:A) -> BLRSBMUTCCIL | Y14: 906 VDI-APP | Z14: 100.112.9.13 | AA14: =_xlfn.XLOOKUP(Z14,Sheet1!B:B,Sheet1!A:A) -> #N/A | AB14: 909 VDI | AC14: 100.112.10.13 | AD14: =_xlfn.XLOOKUP(AC14,Sheet1!B:B,Sheet1!A:A) -> #N/A | AE14: 670 New_APP | AF14: 100.112.12.13 | AG14: =_xlfn.XLOOKUP(AF14,Sheet1!B:B,Sheet1!A:A) -> #N/A | AH14: 902 Server_Proxy | AI14: 100.112.26.13 | AJ14: =_xlfn.XLOOKUP(AI14,Sheet1!B:B,Sheet1!A:A) -> #N/A | AK14: 903 Proxy_to_Int | AL14: 100.112.27.13 | AM14: =_xlfn.XLOOKUP(AL14,Sheet1!B:B,Sheet1!A:A) -> #N/A | AN14: 917 DSD | AO14: 100.112.28.13 | AP14: =_xlfn.XLOOKUP(AO14,Sheet1!B:B,Sheet1!A:A) -> #N/A
B15: 100.112.0.14 | C15: =_xlfn.XLOOKUP(B15,Sheet1!B:B,Sheet1!A:A) -> #N/A | E15: 100.112.1.14 | F15: =_xlfn.XLOOKUP(E15,Sheet1!B:B,Sheet1!A:A) -> BLRSBMPFMSAPP1 | H15: 100.112.2.14 | I15: =_xlfn.XLOOKUP(H15,Sheet1!B:B,Sheet1!A:A) -> #N/A | J15: NAT_SUB 916 | K15: 100.112.3.14 | L15: =_xlfn.XLOOKUP(K15,Sheet1!B:B,Sheet1!A:A) -> #N/A | N15: 100.112.4.14 | O15: =_xlfn.XLOOKUP(N15,Sheet1!B:B,Sheet1!A:A) -> #N/A | P15: 867 UAT_WEB_WEB-E | Q15: 100.112.5.14 | R15: =_xlfn.XLOOKUP(Q15,Sheet1!B:B,Sheet1!A:A) -> #N/A | T15: 100.112.6.14 | U15: =_xlfn.XLOOKUP(T15,Sheet1!B:B,Sheet1!A:A) -> #N/A | V15: 912 UAT_APP2 | W15: 100.112.7.14 | X15: =_xlfn.XLOOKUP(W15,Sheet1!B:B,Sheet1!A:A) -> #N/A | Y15: 906 VDI-APP | Z15: 100.112.9.14 | AA15: =_xlfn.XLOOKUP(Z15,Sheet1!B:B,Sheet1!A:A) -> #N/A | AB15: 909 VDI | AC15: 100.112.10.14 | AD15: =_xlfn.XLOOKUP(AC15,Sheet1!B:B,Sheet1!A:A) -> #N/A | AE15: 670 New_APP | AF15: 100.112.12.14 | AG15: =_xlfn.XLOOKUP(AF15,Sheet1!B:B,Sheet1!A:A) -> #N/A | AH15: 902 Server_Proxy | AI15: 100.112.26.14 | AJ15: =_xlfn.XLOOKUP(AI15,Sheet1!B:B,Sheet1!A:A) -> #N/A | AK15: 903 Proxy_to_Int | AL15: 100.112.27.14 | AM15: =_xlfn.XLOOKUP(AL15,Sheet1!B:B,Sheet1!A:A) -> #N/A | AN15: 917 DSD | AO15: 100.112.28.14 | AP15: =_xlfn.XLOOKUP(AO15,Sheet1!B:B,Sheet1!A:A) -> #N/A
B16: 100.112.0.15 | C16: =_xlfn.XLOOKUP(B16,Sheet1!B:B,Sheet1!A:A) -> #N/A | E16: 100.112.1.15 | F16: =_xlfn.XLOOKUP(E16,Sheet1!B:B,Sheet1!A:A) -> BLRSBMAXIAPPRE01 | H16: 100.112.2.15 | I16: =_xlfn.XLOOKUP(H16,Sheet1!B:B,Sheet1!A:A) -> #N/A | J16: NAT_SUB 916 | K16: 100.112.3.15 | L16: =_xlfn.XLOOKUP(K16,Sheet1!B:B,Sheet1!A:A) -> #N/A | N16: 100.112.4.15 | O16: =_xlfn.XLOOKUP(N16,Sheet1!B:B,Sheet1!A:A) -> #N/A | P16: 867 UAT_WEB_WEB-E | Q16: 100.112.5.15 | R16: =_xlfn.XLOOKUP(Q16,Sheet1!B:B,Sheet1!A:A) -> #N/A | T16: 100.112.6.15 | U16: =_xlfn.XLOOKUP(T16,Sheet1!B:B,Sheet1!A:A) -> #N/A | V16: 912 UAT_APP2 | W16: 100.112.7.15 | X16: =_xlfn.XLOOKUP(W16,Sheet1!B:B,Sheet1!A:A) -> BLRSBMUTAMLAPP2 | Y16: 906 VDI-APP | Z16: 100.112.9.15 | AA16: =_xlfn.XLOOKUP(Z16,Sheet1!B:B,Sheet1!A:A) -> #N/A | AB16: 909 VDI | AC16: 100.112.10.15 | AD16: =_xlfn.XLOOKUP(AC16,Sheet1!B:B,Sheet1!A:A) -> #N/A | AE16: 670 New_APP | AF16: 100.112.12.15 | AG16: =_xlfn.XLOOKUP(AF16,Sheet1!B:B,Sheet1!A:A) -> #N/A | AI16: 100.112.26.15 | AJ16: =_xlfn.XLOOKUP(AI16,Sheet1!B:B,Sheet1!A:A) -> #N/A | AL16: 100.112.27.15 | AM16: =_xlfn.XLOOKUP(AL16,Sheet1!B:B,Sheet1!A:A) -> #N/A | AN16: 917 DSD | AO16: 100.112.28.15 | AP16: =_xlfn.XLOOKUP(AO16,Sheet1!B:B,Sheet1!A:A) -> #N/A
B17: 100.112.0.16 | C17: =_xlfn.XLOOKUP(B17,Sheet1!B:B,Sheet1!A:A) -> #N/A | E17: 100.112.1.16 | F17: =_xlfn.XLOOKUP(E17,Sheet1!B:B,Sheet1!A:A) -> BLRSBMAXIAPPDP01 | H17: 100.112.2.16 | I17: =_xlfn.XLOOKUP(H17,Sheet1!B:B,Sheet1!A:A) -> #N/A | J17: NAT_SUB 916 | K17: 100.112.3.16 | L17: =_xlfn.XLOOKUP(K17,Sheet1!B:B,Sheet1!A:A) -> #N/A | N17: 100.112.4.16 | O17: =_xlfn.XLOOKUP(N17,Sheet1!B:B,Sheet1!A:A) -> #N/A | P17: 867 UAT_WEB_WEB-E | Q17: 100.112.5.16 | R17: =_xlfn.XLOOKUP(Q17,Sheet1!B:B,Sheet1!A:A) -> #N/A | T17: 100.112.6.16 | U17: =_xlfn.XLOOKUP(T17,Sheet1!B:B,Sheet1!A:A) -> #N/A | V17: 912 UAT_APP2 | W17: 100.112.7.16 | X17: =_xlfn.XLOOKUP(W17,Sheet1!B:B,Sheet1!A:A) -> BLRSBMUTCCTAPP | Y17: 906 VDI-APP | Z17: 100.112.9.16 | AA17: =_xlfn.XLOOKUP(Z17,Sheet1!B:B,Sheet1!A:A) -> #N/A | AB17: 909 VDI | AC17: 100.112.10.16 | AD17: =_xlfn.XLOOKUP(AC17,Sheet1!B:B,Sheet1!A:A) -> #N/A | AE17: 670 New_APP | AF17: 100.112.12.16 | AG17: =_xlfn.XLOOKUP(AF17,Sheet1!B:B,Sheet1!A:A) -> #N/A | AI17: 100.112.26.16 | AJ17: =_xlfn.XLOOKUP(AI17,Sheet1!B:B,Sheet1!A:A) -> #N/A | AL17: 100.112.27.16 | AM17: =_xlfn.XLOOKUP(AL17,Sheet1!B:B,Sheet1!A:A) -> #N/A | AN17: 917 DSD | AO17: 100.112.28.16 | AP17: =_xlfn.XLOOKUP(AO17,Sheet1!B:B,Sheet1!A:A) -> #N/A
B18: 100.112.0.17 | C18: =_xlfn.XLOOKUP(B18,Sheet1!B:B,Sheet1!A:A) -> #N/A | E18: 100.112.1.17 | F18: =_xlfn.XLOOKUP(E18,Sheet1!B:B,Sheet1!A:A) -> BANSBMCRMPRODAP | H18: 100.112.2.17 | I18: =_xlfn.XLOOKUP(H18,Sheet1!B:B,Sheet1!A:A) -> #N/A | J18: NAT_SUB 916 | K18: 100.112.3.17 | L18: =_xlfn.XLOOKUP(K18,Sheet1!B:B,Sheet1!A:A) -> #N/A | N18: 100.112.4.17 | O18: =_xlfn.XLOOKUP(N18,Sheet1!B:B,Sheet1!A:A) -> #N/A | P18: 867 UAT_WEB_WEB-E | Q18: 100.112.5.17 | R18: =_xlfn.XLOOKUP(Q18,Sheet1!B:B,Sheet1!A:A) -> BLRSBMPFMUATAPP | T18: 100.112.6.17 | U18: =_xlfn.XLOOKUP(T18,Sheet1!B:B,Sheet1!A:A) -> #N/A | V18: 912 UAT_APP2 | W18: 100.112.7.17 | X18: =_xlfn.XLOOKUP(W18,Sheet1!B:B,Sheet1!A:A) -> BLRSBMUTCKYCAP | Y18: 906 VDI-APP | Z18: 100.112.9.17 | AA18: =_xlfn.XLOOKUP(Z18,Sheet1!B:B,Sheet1!A:A) -> #N/A | AB18: 909 VDI | AC18: 100.112.10.17 | AD18: =_xlfn.XLOOKUP(AC18,Sheet1!B:B,Sheet1!A:A) -> #N/A | AE18: 670 New_APP | AF18: 100.112.12.17 | AG18: =_xlfn.XLOOKUP(AF18,Sheet1!B:B,Sheet1!A:A) -> #N/A | AI18: 100.112.26.17 | AJ18: =_xlfn.XLOOKUP(AI18,Sheet1!B:B,Sheet1!A:A) -> #N/A | AL18: 100.112.27.17 | AM18: =_xlfn.XLOOKUP(AL18,Sheet1!B:B,Sheet1!A:A) -> #N/A | AN18: 917 DSD | AO18: 100.112.28.17 | AP18: =_xlfn.XLOOKUP(AO18,Sheet1!B:B,Sheet1!A:A) -> #N/A
B19: 100.112.0.18 | C19: =_xlfn.XLOOKUP(B19,Sheet1!B:B,Sheet1!A:A) -> #N/A | E19: 100.112.1.18 | F19: =_xlfn.XLOOKUP(E19,Sheet1!B:B,Sheet1!A:A) -> BLRSBMDRFMSAPP | H19: 100.112.2.18 | I19: =_xlfn.XLOOKUP(H19,Sheet1!B:B,Sheet1!A:A) -> #N/A | J19: NAT_SUB 916 | K19: 100.112.3.18 | L19: =_xlfn.XLOOKUP(K19,Sheet1!B:B,Sheet1!A:A) -> #N/A | N19: 100.112.4.18 | O19: =_xlfn.XLOOKUP(N19,Sheet1!B:B,Sheet1!A:A) -> #N/A | P19: 867 UAT_WEB_WEB-E | Q19: 100.112.5.18 | R19: =_xlfn.XLOOKUP(Q19,Sheet1!B:B,Sheet1!A:A) -> BLRSBMPFMUATDB | T19: 100.112.6.18 | U19: =_xlfn.XLOOKUP(T19,Sheet1!B:B,Sheet1!A:A) -> #N/A | V19: 912 UAT_APP2 | W19: 100.112.7.18 | X19: =_xlfn.XLOOKUP(W19,Sheet1!B:B,Sheet1!A:A) -> BLRSBMUTCKYCAP2 | Y19: 907 VDI-WEB | Z19: 100.112.9.18 | AA19: =_xlfn.XLOOKUP(Z19,Sheet1!B:B,Sheet1!A:A) -> BLRSBMVDIUAG01 | AB19: 909 VDI | AC19: 100.112.10.18 | AD19: =_xlfn.XLOOKUP(AC19,Sheet1!B:B,Sheet1!A:A) -> #N/A | AE19: 670 New_APP | AF19: 100.112.12.18 | AG19: =_xlfn.XLOOKUP(AF19,Sheet1!B:B,Sheet1!A:A) -> #N/A | AI19: 100.112.26.18 | AJ19: =_xlfn.XLOOKUP(AI19,Sheet1!B:B,Sheet1!A:A) -> #N/A | AL19: 100.112.27.18 | AM19: =_xlfn.XLOOKUP(AL19,Sheet1!B:B,Sheet1!A:A) -> #N/A | AN19: 917 DSD | AO19: 100.112.28.18 | AP19: =_xlfn.XLOOKUP(AO19,Sheet1!B:B,Sheet1!A:A) -> #N/A
B20: 100.112.0.19 | C20: =_xlfn.XLOOKUP(B20,Sheet1!B:B,Sheet1!A:A) -> #N/A | E20: 100.112.1.19 | F20: =_xlfn.XLOOKUP(E20,Sheet1!B:B,Sheet1!A:A) -> #N/A | H20: 100.112.2.19 | I20: =_xlfn.XLOOKUP(H20,Sheet1!B:B,Sheet1!A:A) -> #N/A | J20: NAT_SUB 916 | K20: 100.112.3.19 | L20: =_xlfn.XLOOKUP(K20,Sheet1!B:B,Sheet1!A:A) -> #N/A | N20: 100.112.4.19 | O20: =_xlfn.XLOOKUP(N20,Sheet1!B:B,Sheet1!A:A) -> #N/A | P20: 867 UAT_WEB_WEB-E | Q20: 100.112.5.19 | R20: =_xlfn.XLOOKUP(Q20,Sheet1!B:B,Sheet1!A:A) -> BLRSBMD2K | T20: 100.112.6.19 | U20: =_xlfn.XLOOKUP(T20,Sheet1!B:B,Sheet1!A:A) -> #N/A | V20: 912 UAT_APP2 | W20: 100.112.7.19 | X20: =_xlfn.XLOOKUP(W20,Sheet1!B:B,Sheet1!A:A) -> BLRSBMIVRUTAP1 | Y20: 907 VDI-WEB | Z20: 100.112.9.19 | AA20: =_xlfn.XLOOKUP(Z20,Sheet1!B:B,Sheet1!A:A) -> #N/A | AB20: 909 VDI | AC20: 100.112.10.19 | AD20: =_xlfn.XLOOKUP(AC20,Sheet1!B:B,Sheet1!A:A) -> #N/A | AE20: 670 New_APP | AF20: 100.112.12.19 | AG20: =_xlfn.XLOOKUP(AF20,Sheet1!B:B,Sheet1!A:A) -> #N/A | AI20: 100.112.26.19 | AJ20: =_xlfn.XLOOKUP(AI20,Sheet1!B:B,Sheet1!A:A) -> #N/A | AL20: 100.112.27.19 | AM20: =_xlfn.XLOOKUP(AL20,Sheet1!B:B,Sheet1!A:A) -> #N/A | AN20: 917 DSD | AO20: 100.112.28.19 | AP20: =_xlfn.XLOOKUP(AO20,Sheet1!B:B,Sheet1!A:A) -> #N/A
B21: 100.112.0.20 | C21: =_xlfn.XLOOKUP(B21,Sheet1!B:B,Sheet1!A:A) -> #N/A | E21: 100.112.1.20 | F21: =_xlfn.XLOOKUP(E21,Sheet1!B:B,Sheet1!A:A) -> BLRSBMAMLAPP1 | H21: 100.112.2.20 | I21: =_xlfn.XLOOKUP(H21,Sheet1!B:B,Sheet1!A:A) -> #N/A | J21: NAT_SUB 916 | K21: 100.112.3.20 | L21: =_xlfn.XLOOKUP(K21,Sheet1!B:B,Sheet1!A:A) -> #N/A | N21: 100.112.4.20 | O21: =_xlfn.XLOOKUP(N21,Sheet1!B:B,Sheet1!A:A) -> #N/A | P21: 867 UAT_WEB_WEB-E | Q21: 100.112.5.20 | R21: =_xlfn.XLOOKUP(Q21,Sheet1!B:B,Sheet1!A:A) -> BLRSBMWEB2 | T21: 100.112.6.20 | U21: =_xlfn.XLOOKUP(T21,Sheet1!B:B,Sheet1!A:A) -> #N/A | V21: 912 UAT_APP2 | W21: 100.112.7.20 | X21: =_xlfn.XLOOKUP(W21,Sheet1!B:B,Sheet1!A:A) -> BLRSBMIVRUTAP2 | Y21: 907 VDI-WEB | Z21: 100.112.9.20 | AA21: =_xlfn.XLOOKUP(Z21,Sheet1!B:B,Sheet1!A:A) -> #N/A | AB21: 909 VDI | AC21: 100.112.10.20 | AD21: =_xlfn.XLOOKUP(AC21,Sheet1!B:B,Sheet1!A:A) -> #N/A | AE21: 670 New_APP | AF21: 100.112.12.20 | AG21: =_xlfn.XLOOKUP(AF21,Sheet1!B:B,Sheet1!A:A) -> #N/A | AI21: 100.112.26.20 | AJ21: =_xlfn.XLOOKUP(AI21,Sheet1!B:B,Sheet1!A:A) -> #N/A | AL21: 100.112.27.20 | AM21: =_xlfn.XLOOKUP(AL21,Sheet1!B:B,Sheet1!A:A) -> #N/A | AN21: 917 DSD | AO21: 100.112.28.20 | AP21: =_xlfn.XLOOKUP(AO21,Sheet1!B:B,Sheet1!A:A) -> #N/A
B22: 100.112.0.21 | C22: =_xlfn.XLOOKUP(B22,Sheet1!B:B,Sheet1!A:A) -> #N/A | E22: 100.112.1.21 | F22: =_xlfn.XLOOKUP(E22,Sheet1!B:B,Sheet1!A:A) -> BLRSBMEFTAPP1 | H22: 100.112.2.21 | I22: =_xlfn.XLOOKUP(H22,Sheet1!B:B,Sheet1!A:A) -> #N/A | J22: NAT_SUB 916 | K22: 100.112.3.21 | L22: =_xlfn.XLOOKUP(K22,Sheet1!B:B,Sheet1!A:A) -> #N/A | N22: 100.112.4.21 | O22: =_xlfn.XLOOKUP(N22,Sheet1!B:B,Sheet1!A:A) -> #N/A | P22: 867 UAT_WEB_WEB-E | Q22: 100.112.5.21 | R22: =_xlfn.XLOOKUP(Q22,Sheet1!B:B,Sheet1!A:A) -> #N/A | T22: 100.112.6.21 | U22: =_xlfn.XLOOKUP(T22,Sheet1!B:B,Sheet1!A:A) -> #N/A | V22: 912 UAT_APP2 | W22: 100.112.7.21 | X22: =_xlfn.XLOOKUP(W22,Sheet1!B:B,Sheet1!A:A) -> #N/A | Y22: 907 VDI-WEB | Z22: 100.112.9.21 | AA22: =_xlfn.XLOOKUP(Z22,Sheet1!B:B,Sheet1!A:A) -> #N/A | AB22: 909 VDI | AC22: 100.112.10.21 | AD22: =_xlfn.XLOOKUP(AC22,Sheet1!B:B,Sheet1!A:A) -> #N/A | AE22: 670 New_APP | AF22: 100.112.12.21 | AG22: =_xlfn.XLOOKUP(AF22,Sheet1!B:B,Sheet1!A:A) -> #N/A | AI22: 100.112.26.21 | AJ22: =_xlfn.XLOOKUP(AI22,Sheet1!B:B,Sheet1!A:A) -> #N/A | AL22: 100.112.27.21 | AM22: =_xlfn.XLOOKUP(AL22,Sheet1!B:B,Sheet1!A:A) -> #N/A | AN22: 917 DSD | AO22: 100.112.28.21 | AP22: =_xlfn.XLOOKUP(AO22,Sheet1!B:B,Sheet1!A:A) -> #N/A
B23: 100.112.0.22 | C23: =_xlfn.XLOOKUP(B23,Sheet1!B:B,Sheet1!A:A) -> #N/A | E23: 100.112.1.22 | F23: =_xlfn.XLOOKUP(E23,Sheet1!B:B,Sheet1!A:A) -> BLRSBMDRSFMSMQ | H23: 100.112.2.22 | I23: =_xlfn.XLOOKUP(H23,Sheet1!B:B,Sheet1!A:A) -> #N/A | J23: NAT_SUB 916 | K23: 100.112.3.22 | L23: =_xlfn.XLOOKUP(K23,Sheet1!B:B,Sheet1!A:A) -> #N/A | N23: 100.112.4.22 | O23: =_xlfn.XLOOKUP(N23,Sheet1!B:B,Sheet1!A:A) -> #N/A | P23: 867 UAT_WEB_WEB-E | Q23: 100.112.5.22 | R23: =_xlfn.XLOOKUP(Q23,Sheet1!B:B,Sheet1!A:A) -> BLRSBMUATPRYJWEB01 | T23: 100.112.6.22 | U23: =_xlfn.XLOOKUP(T23,Sheet1!B:B,Sheet1!A:A) -> #N/A | V23: 912 UAT_APP2 | W23: 100.112.7.22 | X23: =_xlfn.XLOOKUP(W23,Sheet1!B:B,Sheet1!A:A) -> #N/A | Y23: 907 VDI-WEB | Z23: 100.112.9.22 | AA23: =_xlfn.XLOOKUP(Z23,Sheet1!B:B,Sheet1!A:A) -> #N/A | AB23: 909 VDI | AC23: 100.112.10.22 | AD23: =_xlfn.XLOOKUP(AC23,Sheet1!B:B,Sheet1!A:A) -> #N/A | AE23: 670 New_APP | AF23: 100.112.12.22 | AG23: =_xlfn.XLOOKUP(AF23,Sheet1!B:B,Sheet1!A:A) -> #N/A | AI23: 100.112.26.22 | AJ23: =_xlfn.XLOOKUP(AI23,Sheet1!B:B,Sheet1!A:A) -> #N/A | AL23: 100.112.27.22 | AM23: =_xlfn.XLOOKUP(AL23,Sheet1!B:B,Sheet1!A:A) -> #N/A | AN23: 917 DSD | AO23: 100.112.28.22 | AP23: =_xlfn.XLOOKUP(AO23,Sheet1!B:B,Sheet1!A:A) -> #N/A
B24: 100.112.0.23 | C24: =_xlfn.XLOOKUP(B24,Sheet1!B:B,Sheet1!A:A) -> #N/A | E24: 100.112.1.23 | F24: =_xlfn.XLOOKUP(E24,Sheet1!B:B,Sheet1!A:A) -> BLRSBMFINJBOSS1 | H24: 100.112.2.23 | I24: =_xlfn.XLOOKUP(H24,Sheet1!B:B,Sheet1!A:A) -> #N/A | J24: NAT_SUB 916 | K24: 100.112.3.23 | L24: =_xlfn.XLOOKUP(K24,Sheet1!B:B,Sheet1!A:A) -> #N/A | N24: 100.112.4.23 | O24: =_xlfn.XLOOKUP(N24,Sheet1!B:B,Sheet1!A:A) -> #N/A | P24: 867 UAT_WEB_WEB-E | Q24: 100.112.5.23 | R24: =_xlfn.XLOOKUP(Q24,Sheet1!B:B,Sheet1!A:A) -> BLRSBMUATBMLWEB01 | T24: 100.112.6.23 | U24: =_xlfn.XLOOKUP(T24,Sheet1!B:B,Sheet1!A:A) -> #N/A | V24: 912 UAT_APP2 | W24: 100.112.7.23 | X24: =_xlfn.XLOOKUP(W24,Sheet1!B:B,Sheet1!A:A) -> BLRSBMUTCAMAP1 | Y24: 907 VDI-WEB | Z24: 100.112.9.23 | AA24: =_xlfn.XLOOKUP(Z24,Sheet1!B:B,Sheet1!A:A) -> #N/A | AB24: 909 VDI | AC24: 100.112.10.23 | AD24: =_xlfn.XLOOKUP(AC24,Sheet1!B:B,Sheet1!A:A) -> #N/A | AE24: 670 New_APP | AF24: 100.112.12.23 | AG24: =_xlfn.XLOOKUP(AF24,Sheet1!B:B,Sheet1!A:A) -> #N/A | AI24: 100.112.26.23 | AJ24: =_xlfn.XLOOKUP(AI24,Sheet1!B:B,Sheet1!A:A) -> #N/A | AL24: 100.112.27.23 | AM24: =_xlfn.XLOOKUP(AL24,Sheet1!B:B,Sheet1!A:A) -> #N/A | AN24: 917 DSD | AO24: 100.112.28.23 | AP24: =_xlfn.XLOOKUP(AO24,Sheet1!B:B,Sheet1!A:A) -> #N/A
B25: 100.112.0.24 | C25: =_xlfn.XLOOKUP(B25,Sheet1!B:B,Sheet1!A:A) -> #N/A | E25: 100.112.1.24 | F25: =_xlfn.XLOOKUP(E25,Sheet1!B:B,Sheet1!A:A) -> BLRSBMCSISAPP01 | H25: 100.112.2.24 | I25: =_xlfn.XLOOKUP(H25,Sheet1!B:B,Sheet1!A:A) -> #N/A | J25: NAT_SUB 916 | K25: 100.112.3.24 | L25: =_xlfn.XLOOKUP(K25,Sheet1!B:B,Sheet1!A:A) -> #N/A | N25: 100.112.4.24 | O25: =_xlfn.XLOOKUP(N25,Sheet1!B:B,Sheet1!A:A) -> #N/A | P25: 867 UAT_WEB_WEB-E | Q25: 100.112.5.24 | R25: =_xlfn.XLOOKUP(Q25,Sheet1!B:B,Sheet1!A:A) -> BLRSBMUATRDLWEB01 | T25: 100.112.6.24 | U25: =_xlfn.XLOOKUP(T25,Sheet1!B:B,Sheet1!A:A) -> #N/A | V25: 912 UAT_APP2 | W25: 100.112.7.24 | X25: =_xlfn.XLOOKUP(W25,Sheet1!B:B,Sheet1!A:A) -> BLRSBMUTFRMAPP | Y25: 907 VDI-WEB | Z25: 100.112.9.24 | AA25: =_xlfn.XLOOKUP(Z25,Sheet1!B:B,Sheet1!A:A) -> #N/A | AB25: 909 VDI | AC25: 100.112.10.24 | AD25: =_xlfn.XLOOKUP(AC25,Sheet1!B:B,Sheet1!A:A) -> #N/A | AE25: 670 New_APP | AF25: 100.112.12.24 | AG25: =_xlfn.XLOOKUP(AF25,Sheet1!B:B,Sheet1!A:A) -> #N/A | AI25: 100.112.26.24 | AJ25: =_xlfn.XLOOKUP(AI25,Sheet1!B:B,Sheet1!A:A) -> #N/A | AL25: 100.112.27.24 | AM25: =_xlfn.XLOOKUP(AL25,Sheet1!B:B,Sheet1!A:A) -> #N/A | AN25: 917 DSD | AO25: 100.112.28.24 | AP25: =_xlfn.XLOOKUP(AO25,Sheet1!B:B,Sheet1!A:A) -> #N/A
B26: 100.112.0.25 | C26: =_xlfn.XLOOKUP(B26,Sheet1!B:B,Sheet1!A:A) -> #N/A | E26: 100.112.1.25 | F26: =_xlfn.XLOOKUP(E26,Sheet1!B:B,Sheet1!A:A) -> #N/A | H26: 100.112.2.25 | I26: =_xlfn.XLOOKUP(H26,Sheet1!B:B,Sheet1!A:A) -> #N/A | J26: NAT_SUB 916 | K26: 100.112.3.25 | L26: =_xlfn.XLOOKUP(K26,Sheet1!B:B,Sheet1!A:A) -> #N/A | N26: 100.112.4.25 | O26: =_xlfn.XLOOKUP(N26,Sheet1!B:B,Sheet1!A:A) -> #N/A | P26: 867 UAT_WEB_WEB-E | Q26: 100.112.5.25 | R26: =_xlfn.XLOOKUP(Q26,Sheet1!B:B,Sheet1!A:A) -> BLRSBMUATRDLWEB02 | T26: 100.112.6.25 | U26: =_xlfn.XLOOKUP(T26,Sheet1!B:B,Sheet1!A:A) -> #N/A | V26: 912 UAT_APP2 | W26: 100.112.7.25 | X26: =_xlfn.XLOOKUP(W26,Sheet1!B:B,Sheet1!A:A) -> #N/A | Y26: 907 VDI-WEB | Z26: 100.112.9.25 | AA26: =_xlfn.XLOOKUP(Z26,Sheet1!B:B,Sheet1!A:A) -> #N/A | AB26: 909 VDI | AC26: 100.112.10.25 | AD26: =_xlfn.XLOOKUP(AC26,Sheet1!B:B,Sheet1!A:A) -> #N/A | AE26: 670 New_APP | AF26: 100.112.12.25 | AG26: =_xlfn.XLOOKUP(AF26,Sheet1!B:B,Sheet1!A:A) -> #N/A | AI26: 100.112.26.25 | AJ26: =_xlfn.XLOOKUP(AI26,Sheet1!B:B,Sheet1!A:A) -> #N/A | AL26: 100.112.27.25 | AM26: =_xlfn.XLOOKUP(AL26,Sheet1!B:B,Sheet1!A:A) -> #N/A | AN26: 917 DSD | AO26: 100.112.28.25 | AP26: =_xlfn.XLOOKUP(AO26,Sheet1!B:B,Sheet1!A:A) -> #N/A
B27: 100.112.0.26 | C27: =_xlfn.XLOOKUP(B27,Sheet1!B:B,Sheet1!A:A) -> #N/A | E27: 100.112.1.26 | F27: =_xlfn.XLOOKUP(E27,Sheet1!B:B,Sheet1!A:A) -> BLRSBMWEBNEW | H27: 100.112.2.26 | I27: =_xlfn.XLOOKUP(H27,Sheet1!B:B,Sheet1!A:A) -> #N/A | J27: NAT_SUB 916 | K27: 100.112.3.26 | L27: =_xlfn.XLOOKUP(K27,Sheet1!B:B,Sheet1!A:A) -> #N/A | N27: 100.112.4.26 | O27: =_xlfn.XLOOKUP(N27,Sheet1!B:B,Sheet1!A:A) -> #N/A | P27: 867 UAT_WEB_WEB-E | Q27: 100.112.5.26 | R27: =_xlfn.XLOOKUP(Q27,Sheet1!B:B,Sheet1!A:A) -> #N/A | T27: 100.112.6.26 | U27: =_xlfn.XLOOKUP(T27,Sheet1!B:B,Sheet1!A:A) -> #N/A | V27: 912 UAT_APP2 | W27: 100.112.7.26 | X27: =_xlfn.XLOOKUP(W27,Sheet1!B:B,Sheet1!A:A) -> BLRSBMCNTRVAPOC | Y27: 907 VDI-WEB | Z27: 100.112.9.26 | AA27: =_xlfn.XLOOKUP(Z27,Sheet1!B:B,Sheet1!A:A) -> #N/A | AB27: 909 VDI | AC27: 100.112.10.26 | AD27: =_xlfn.XLOOKUP(AC27,Sheet1!B:B,Sheet1!A:A) -> #N/A | AE27: 670 New_APP | AF27: 100.112.12.26 | AG27: =_xlfn.XLOOKUP(AF27,Sheet1!B:B,Sheet1!A:A) -> #N/A | AI27: 100.112.26.26 | AJ27: =_xlfn.XLOOKUP(AI27,Sheet1!B:B,Sheet1!A:A) -> #N/A | AL27: 100.112.27.26 | AM27: =_xlfn.XLOOKUP(AL27,Sheet1!B:B,Sheet1!A:A) -> #N/A | AN27: 917 DSD | AO27: 100.112.28.26 | AP27: =_xlfn.XLOOKUP(AO27,Sheet1!B:B,Sheet1!A:A) -> #N/A
... B32: 100.112.0.31 | C32: =_xlfn.XLOOKUP(B32,Sheet1!B:B,Sheet1!A:A) -> #N/A | E32: 100.112.1.31 | F32: =_xlfn.XLOOKUP(E32,Sheet1!B:B,Sheet1!A:A) -> BLRSBMACIAPP01 | H32: 100.112.2.31 | I32: =_xlfn.XLOOKUP(H32,Sheet1!B:B,Sheet1!A:A) -> #N/A | J32: NAT_SUB 916 | K32: 100.112.3.31 | L32: =_xlfn.XLOOKUP(K32,Sheet1!B:B,Sheet1!A:A) -> #N/A | N32: 100.112.4.31 | O32: =_xlfn.XLOOKUP(N32,Sheet1!B:B,Sheet1!A:A) -> #N/A | P32: 867 UAT_WEB_WEB-E | Q32: 100.112.5.31 | R32: =_xlfn.XLOOKUP(Q32,Sheet1!B:B,Sheet1!A:A) -> #N/A | T32: 100.112.6.31 | U32: =_xlfn.XLOOKUP(T32,Sheet1!B:B,Sheet1!A:A) -> #N/A | V32: 912 UAT_APP2 | W32: 100.112.7.31 | X32: =_xlfn.XLOOKUP(W32,Sheet1!B:B,Sheet1!A:A) -> #N/A | Y32: 907 VDI-WEB | Z32: 100.112.9.31 | AA32: =_xlfn.XLOOKUP(Z32,Sheet1!B:B,Sheet1!A:A) -> #N/A | AB32: 909 VDI | AC32: 100.112.10.31 | AD32: =_xlfn.XLOOKUP(AC32,Sheet1!B:B,Sheet1!A:A) -> #N/A | AE32: 670 New_APP | AF32: 100.112.12.31 | AG32: =_xlfn.XLOOKUP(AF32,Sheet1!B:B,Sheet1!A:A) -> #N/A | AI32: 100.112.26.31 | AJ32: =_xlfn.XLOOKUP(AI32,Sheet1!B:B,Sheet1!A:A) -> #N/A | AL32: 100.112.27.31 | AM32: =_xlfn.XLOOKUP(AL32,Sheet1!B:B,Sheet1!A:A) -> #N/A | AN32: 917 DSD | AO32: 100.112.28.31 | AP32: =_xlfn.XLOOKUP(AO32,Sheet1!B:B,Sheet1!A:A) -> #N/A
B33: 100.112.0.32 | C33: =_xlfn.XLOOKUP(B33,Sheet1!B:B,Sheet1!A:A) -> #N/A | E33: 100.112.1.32 | F33: =_xlfn.XLOOKUP(E33,Sheet1!B:B,Sheet1!A:A) -> BANSBMKDMSAPP | H33: 100.112.2.32 | I33: =_xlfn.XLOOKUP(H33,Sheet1!B:B,Sheet1!A:A) -> #N/A | J33: NAT_SUB 916 | K33: 100.112.3.32 | L33: =_xlfn.XLOOKUP(K33,Sheet1!B:B,Sheet1!A:A) -> #N/A | M33: 866 UAT-WEBJAP | N33: 100.112.4.32 | O33: =_xlfn.XLOOKUP(N33,Sheet1!B:B,Sheet1!A:A) -> #N/A | P33: 867 UAT_WEB_WEB-E | Q33: 100.112.5.32 | R33: =_xlfn.XLOOKUP(Q33,Sheet1!B:B,Sheet1!A:A) -> #N/A | T33: 100.112.6.32 | U33: =_xlfn.XLOOKUP(T33,Sheet1!B:B,Sheet1!A:A) -> #N/A | V33: 912 UAT_APP2 | W33: 100.112.7.32 | X33: =_xlfn.XLOOKUP(W33,Sheet1!B:B,Sheet1!A:A) -> #N/A | Y33: 907 VDI-WEB | Z33: 100.112.9.32 | AA33: =_xlfn.XLOOKUP(Z33,Sheet1!B:B,Sheet1!A:A) -> #N/A | AB33: 909 VDI | AC33: 100.112.10.32 | AD33: =_xlfn.XLOOKUP(AC33,Sheet1!B:B,Sheet1!A:A) -> #N/A | AE33: 670 New_APP | AF33: 100.112.12.32 | AG33: =_xlfn.XLOOKUP(AF33,Sheet1!B:B,Sheet1!A:A) -> #N/A | AI33: 100.112.26.32 | AJ33: =_xlfn.XLOOKUP(AI33,Sheet1!B:B,Sheet1!A:A) -> #N/A | AL33: 100.112.27.32 | AM33: =_xlfn.XLOOKUP(AL33,Sheet1!B:B,Sheet1!A:A) -> #N/A | AN33: 917 DSD | AO33: 100.112.28.32 | AP33: =_xlfn.XLOOKUP(AO33,Sheet1!B:B,Sheet1!A:A) -> #N/A
B34: 100.112.0.33 | C34: =_xlfn.XLOOKUP(B34,Sheet1!B:B,Sheet1!A:A) -> #N/A | E34: 100.112.1.33 | F34: =_xlfn.XLOOKUP(E34,Sheet1!B:B,Sheet1!A:A) -> BLRSBMUATRFMSA1 | H34: 100.112.2.33 | I34: =_xlfn.XLOOKUP(H34,Sheet1!B:B,Sheet1!A:A) -> #N/A | J34: NAT_SUB 916 | K34: 100.112.3.33 | L34: =_xlfn.XLOOKUP(K34,Sheet1!B:B,Sheet1!A:A) -> #N/A | M34: 866 UAT-WEBJAP | N34: 100.112.4.33 | O34: =_xlfn.XLOOKUP(N34,Sheet1!B:B,Sheet1!A:A) -> #N/A | P34: 865 UAT-WEB-I | Q34: 100.112.5.33 | R34: =_xlfn.XLOOKUP(Q34,Sheet1!B:B,Sheet1!A:A) -> #N/A | S34: 872 AD_Prod | T34: 100.112.6.33 | U34: =_xlfn.XLOOKUP(T34,Sheet1!B:B,Sheet1!A:A) -> #N/A | V34: 912 UAT_APP2 | W34: 100.112.7.33 | X34: =_xlfn.XLOOKUP(W34,Sheet1!B:B,Sheet1!A:A) -> #N/A | Y34: 907 VDI-WEB | Z34: 100.112.9.33 | AA34: =_xlfn.XLOOKUP(Z34,Sheet1!B:B,Sheet1!A:A) -> #N/A | AB34: 909 VDI | AC34: 100.112.10.33 | AD34: =_xlfn.XLOOKUP(AC34,Sheet1!B:B,Sheet1!A:A) -> #N/A | AE34: 670 New_APP | AF34: 100.112.12.33 | AG34: =_xlfn.XLOOKUP(AF34,Sheet1!B:B,Sheet1!A:A) -> #N/A | AI34: 100.112.26.33 | AJ34: =_xlfn.XLOOKUP(AI34,Sheet1!B:B,Sheet1!A:A) -> #N/A | AL34: 100.112.27.33 | AM34: =_xlfn.XLOOKUP(AL34,Sheet1!B:B,Sheet1!A:A) -> #N/A | AN34: 917 DSD | AO34: 100.112.28.33 | AP34: =_xlfn.XLOOKUP(AO34,Sheet1!B:B,Sheet1!A:A) -> #N/A
B35: 100.112.0.34 | C35: =_xlfn.XLOOKUP(B35,Sheet1!B:B,Sheet1!A:A) -> #N/A | E35: 100.112.1.34 | F35: =_xlfn.XLOOKUP(E35,Sheet1!B:B,Sheet1!A:A) -> BLRSBMUATRFMSA2 | H35: 100.112.2.34 | I35: =_xlfn.XLOOKUP(H35,Sheet1!B:B,Sheet1!A:A) -> #N/A | J35: NAT_SUB 916 | K35: 100.112.3.34 | L35: =_xlfn.XLOOKUP(K35,Sheet1!B:B,Sheet1!A:A) -> #N/A | M35: 866 UAT-WEBJAP | N35: 100.112.4.34 | O35: =_xlfn.XLOOKUP(N35,Sheet1!B:B,Sheet1!A:A) -> ASA VLAN Standby | P35: 865 UAT-WEB-I | Q35: 100.112.5.34 | R35: =_xlfn.XLOOKUP(Q35,Sheet1!B:B,Sheet1!A:A) -> ASA VLAN Standby | S35: 872 AD_Prod | T35: 100.112.6.34 | U35: =_xlfn.XLOOKUP(T35,Sheet1!B:B,Sheet1!A:A) -> BLRSBMUATIBPSAPP_VS_443 | V35: 912 UAT_APP2 | W35: 100.112.7.34 | X35: =_xlfn.XLOOKUP(W35,Sheet1!B:B,Sheet1!A:A) -> #N/A | Y35: 908 VDI-DB | Z35: 100.112.9.34 | AA35: =_xlfn.XLOOKUP(Z35,Sheet1!B:B,Sheet1!A:A) -> BLRSBMVDIDB01 | AB35: 909 VDI | AC35: 100.112.10.34 | AD35: =_xlfn.XLOOKUP(AC35,Sheet1!B:B,Sheet1!A:A) -> #N/A | AE35: 670 New_APP | AF35: 100.112.12.34 | AG35: =_xlfn.XLOOKUP(AF35,Sheet1!B:B,Sheet1!A:A) -> #N/A | AI35: 100.112.26.34 | AJ35: =_xlfn.XLOOKUP(AI35,Sheet1!B:B,Sheet1!A:A) -> #N/A | AL35: 100.112.27.34 | AM35: =_xlfn.XLOOKUP(AL35,Sheet1!B:B,Sheet1!A:A) -> #N/A | AN35: 917 DSD | AO35: 100.112.28.34 | AP35: =_xlfn.XLOOKUP(AO35,Sheet1!B:B,Sheet1!A:A) -> #N/A
B36: 100.112.0.35 | C36: =_xlfn.XLOOKUP(B36,Sheet1!B:B,Sheet1!A:A) -> #N/A | E36: 100.112.1.35 | F36: =_xlfn.XLOOKUP(E36,Sheet1!B:B,Sheet1!A:A) -> BLRSBMUATRFMSMQ | H36: 100.112.2.35 | I36: =_xlfn.XLOOKUP(H36,Sheet1!B:B,Sheet1!A:A) -> #N/A | J36: NAT_SUB 916 | K36: 100.112.3.35 | L36: =_xlfn.XLOOKUP(K36,Sheet1!B:B,Sheet1!A:A) -> #N/A | M36: 866 UAT-WEBJAP | N36: 100.112.4.35 | O36: =_xlfn.XLOOKUP(N36,Sheet1!B:B,Sheet1!A:A) -> ASA VLAN Standby | P36: 865 UAT-WEB-I | Q36: 100.112.5.35 | R36: =_xlfn.XLOOKUP(Q36,Sheet1!B:B,Sheet1!A:A) -> ASA VLAN Standby | S36: 872 AD_Prod | T36: 100.112.6.35 | U36: =_xlfn.XLOOKUP(T36,Sheet1!B:B,Sheet1!A:A) -> BLRSBMUATIBPSAPP_VS_8083 | V36: 912 UAT_APP2 | W36: 100.112.7.35 | X36: =_xlfn.XLOOKUP(W36,Sheet1!B:B,Sheet1!A:A) -> #N/A | Y36: 908 VDI-DB | Z36: 100.112.9.35 | AA36: =_xlfn.XLOOKUP(Z36,Sheet1!B:B,Sheet1!A:A) -> #N/A | AB36: 909 VDI | AC36: 100.112.10.35 | AD36: =_xlfn.XLOOKUP(AC36,Sheet1!B:B,Sheet1!A:A) -> #N/A | AE36: 670 New_APP | AF36: 100.112.12.35 | AG36: =_xlfn.XLOOKUP(AF36,Sheet1!B:B,Sheet1!A:A) -> #N/A | AI36: 100.112.26.35 | AJ36: =_xlfn.XLOOKUP(AI36,Sheet1!B:B,Sheet1!A:A) -> #N/A | AL36: 100.112.27.35 | AM36: =_xlfn.XLOOKUP(AL36,Sheet1!B:B,Sheet1!A:A) -> #N/A | AN36: 917 DSD | AO36: 100.112.28.35 | AP36: =_xlfn.XLOOKUP(AO36,Sheet1!B:B,Sheet1!A:A) -> #N/A
B37: 100.112.0.36 | C37: =_xlfn.XLOOKUP(B37,Sheet1!B:B,Sheet1!A:A) -> #N/A | E37: 100.112.1.36 | F37: =_xlfn.XLOOKUP(E37,Sheet1!B:B,Sheet1!A:A) -> BLRSBMADS1 | H37: 100.112.2.36 | I37: =_xlfn.XLOOKUP(H37,Sheet1!B:B,Sheet1!A:A) -> #N/A | J37: NAT_SUB 916 | K37: 100.112.3.36 | L37: =_xlfn.XLOOKUP(K37,Sheet1!B:B,Sheet1!A:A) -> #N/A | M37: 866 UAT-WEBJAP | N37: 100.112.4.36 | O37: =_xlfn.XLOOKUP(N37,Sheet1!B:B,Sheet1!A:A) -> #N/A | P37: 865 UAT-WEB-I | Q37: 100.112.5.36 | R37: =_xlfn.XLOOKUP(Q37,Sheet1!B:B,Sheet1!A:A) -> #N/A | S37: 872 AD_Prod | T37: 100.112.6.36 | U37: =_xlfn.XLOOKUP(T37,Sheet1!B:B,Sheet1!A:A) -> BLRSBMADS | V37: 912 UAT_APP2 | W37: 100.112.7.36 | X37: =_xlfn.XLOOKUP(W37,Sheet1!B:B,Sheet1!A:A) -> #N/A | Y37: 908 VDI-DB | Z37: 100.112.9.36 | AA37: =_xlfn.XLOOKUP(Z37,Sheet1!B:B,Sheet1!A:A) -> #N/A | AB37: 909 VDI | AC37: 100.112.10.36 | AD37: =_xlfn.XLOOKUP(AC37,Sheet1!B:B,Sheet1!A:A) -> #N/A | AE37: 670 New_APP | AF37: 100.112.12.36 | AG37: =_xlfn.XLOOKUP(AF37,Sheet1!B:B,Sheet1!A:A) -> #N/A | AI37: 100.112.26.36 | AJ37: =_xlfn.XLOOKUP(AI37,Sheet1!B:B,Sheet1!A:A) -> #N/A | AL37: 100.112.27.36 | AM37: =_xlfn.XLOOKUP(AL37,Sheet1!B:B,Sheet1!A:A) -> #N/A | AN37: 917 DSD | AO37: 100.112.28.36 | AP37: =_xlfn.XLOOKUP(AO37,Sheet1!B:B,Sheet1!A:A) -> #N/A
B38: 100.112.0.37 | C38: =_xlfn.XLOOKUP(B38,Sheet1!B:B,Sheet1!A:A) -> #N/A | E38: 100.112.1.37 | F38: =_xlfn.XLOOKUP(E38,Sheet1!B:B,Sheet1!A:A) -> BLRSBMCCILSDP01 | H38: 100.112.2.37 | I38: =_xlfn.XLOOKUP(H38,Sheet1!B:B,Sheet1!A:A) -> #N/A | J38: NAT_SUB 916 | K38: 100.112.3.37 | L38: =_xlfn.XLOOKUP(K38,Sheet1!B:B,Sheet1!A:A) -> #N/A | M38: 866 UAT-WEBJAP | N38: 100.112.4.37 | O38: =_xlfn.XLOOKUP(N38,Sheet1!B:B,Sheet1!A:A) -> #N/A | P38: 865 UAT-WEB-I | Q38: 100.112.5.37 | R38: =_xlfn.XLOOKUP(Q38,Sheet1!B:B,Sheet1!A:A) -> #N/A | S38: 872 AD_Prod | T38: 100.112.6.37 | U38: =_xlfn.XLOOKUP(T38,Sheet1!B:B,Sheet1!A:A) -> UAT_100.112.6.37 | V38: 912 UAT_APP2 | W38: 100.112.7.37 | X38: =_xlfn.XLOOKUP(W38,Sheet1!B:B,Sheet1!A:A) -> #N/A | Y38: 908 VDI-DB | Z38: 100.112.9.37 | AA38: =_xlfn.XLOOKUP(Z38,Sheet1!B:B,Sheet1!A:A) -> #N/A | AB38: 909 VDI | AC38: 100.112.10.37 | AD38: =_xlfn.XLOOKUP(AC38,Sheet1!B:B,Sheet1!A:A) -> #N/A | AE38: 670 New_APP | AF38: 100.112.12.37 | AG38: =_xlfn.XLOOKUP(AF38,Sheet1!B:B,Sheet1!A:A) -> #N/A | AI38: 100.112.26.37 | AJ38: =_xlfn.XLOOKUP(AI38,Sheet1!B:B,Sheet1!A:A) -> #N/A | AL38: 100.112.27.37 | AM38: =_xlfn.XLOOKUP(AL38,Sheet1!B:B,Sheet1!A:A) -> #N/A | AN38: 917 DSD | AO38: 100.112.28.37 | AP38: =_xlfn.XLOOKUP(AO38,Sheet1!B:B,Sheet1!A:A) -> #N/A
B39: 100.112.0.38 | C39: =_xlfn.XLOOKUP(B39,Sheet1!B:B,Sheet1!A:A) -> #N/A | E39: 100.112.1.38 | F39: =_xlfn.XLOOKUP(E39,Sheet1!B:B,Sheet1!A:A) -> BLRSBMARST01 | H39: 100.112.2.38 | I39: =_xlfn.XLOOKUP(H39,Sheet1!B:B,Sheet1!A:A) -> #N/A | J39: NAT_SUB 916 | K39: 100.112.3.38 | L39: =_xlfn.XLOOKUP(K39,Sheet1!B:B,Sheet1!A:A) -> #N/A | M39: 866 UAT-WEBJAP | N39: 100.112.4.38 | O39: =_xlfn.XLOOKUP(N39,Sheet1!B:B,Sheet1!A:A) -> #N/A | P39: 865 UAT-WEB-I | Q39: 100.112.5.38 | R39: =_xlfn.XLOOKUP(Q39,Sheet1!B:B,Sheet1!A:A) -> #N/A | S39: 872 AD_Prod | T39: 100.112.6.38 | U39: =_xlfn.XLOOKUP(T39,Sheet1!B:B,Sheet1!A:A) -> BLRSBMPROXYv | V39: 912 UAT_APP2 | W39: 100.112.7.38 | X39: =_xlfn.XLOOKUP(W39,Sheet1!B:B,Sheet1!A:A) -> #N/A | Y39: 908 VDI-DB | Z39: 100.112.9.38 | AA39: =_xlfn.XLOOKUP(Z39,Sheet1!B:B,Sheet1!A:A) -> #N/A | AB39: 909 VDI | AC39: 100.112.10.38 | AD39: =_xlfn.XLOOKUP(AC39,Sheet1!B:B,Sheet1!A:A) -> #N/A | AE39: 670 New_APP | AF39: 100.112.12.38 | AG39: =_xlfn.XLOOKUP(AF39,Sheet1!B:B,Sheet1!A:A) -> #N/A | AI39: 100.112.26.38 | AJ39: =_xlfn.XLOOKUP(AI39,Sheet1!B:B,Sheet1!A:A) -> #N/A | AL39: 100.112.27.38 | AM39: =_xlfn.XLOOKUP(AL39,Sheet1!B:B,Sheet1!A:A) -> #N/A | AN39: 917 DSD | AO39: 100.112.28.38 | AP39: =_xlfn.XLOOKUP(AO39,Sheet1!B:B,Sheet1!A:A) -> #N/A
B40: 100.112.0.39 | C40: =_xlfn.XLOOKUP(B40,Sheet1!B:B,Sheet1!A:A) -> #N/A | E40: 100.112.1.39 | F40: =_xlfn.XLOOKUP(E40,Sheet1!B:B,Sheet1!A:A) -> BLRSBMSOCLG | H40: 100.112.2.39 | I40: =_xlfn.XLOOKUP(H40,Sheet1!B:B,Sheet1!A:A) -> #N/A | J40: NAT_SUB 916 | K40: 100.112.3.39 | L40: =_xlfn.XLOOKUP(K40,Sheet1!B:B,Sheet1!A:A) -> #N/A | M40: 866 UAT-WEBJAP | N40: 100.112.4.39 | O40: =_xlfn.XLOOKUP(N40,Sheet1!B:B,Sheet1!A:A) -> #N/A | P40: 865 UAT-WEB-I | Q40: 100.112.5.39 | R40: =_xlfn.XLOOKUP(Q40,Sheet1!B:B,Sheet1!A:A) -> #N/A | S40: 872 AD_Prod | T40: 100.112.6.39 | U40: =_xlfn.XLOOKUP(T40,Sheet1!B:B,Sheet1!A:A) -> #N/A | V40: 912 UAT_APP2 | W40: 100.112.7.39 | X40: =_xlfn.XLOOKUP(W40,Sheet1!B:B,Sheet1!A:A) -> #N/A | Y40: 908 VDI-DB | Z40: 100.112.9.39 | AA40: =_xlfn.XLOOKUP(Z40,Sheet1!B:B,Sheet1!A:A) -> #N/A | AB40: 909 VDI | AC40: 100.112.10.39 | AD40: =_xlfn.XLOOKUP(AC40,Sheet1!B:B,Sheet1!A:A) -> #N/A | AE40: 670 New_APP | AF40: 100.112.12.39 | AG40: =_xlfn.XLOOKUP(AF40,Sheet1!B:B,Sheet1!A:A) -> #N/A | AI40: 100.112.26.39 | AJ40: =_xlfn.XLOOKUP(AI40,Sheet1!B:B,Sheet1!A:A) -> #N/A | AL40: 100.112.27.39 | AM40: =_xlfn.XLOOKUP(AL40,Sheet1!B:B,Sheet1!A:A) -> #N/A | AN40: 917 DSD | AO40: 100.112.28.39 | AP40: =_xlfn.XLOOKUP(AO40,Sheet1!B:B,Sheet1!A:A) -> #N/A
B41: 100.112.0.40 | C41: =_xlfn.XLOOKUP(B41,Sheet1!B:B,Sheet1!A:A) -> #N/A | E41: 100.112.1.40 | F41: =_xlfn.XLOOKUP(E41,Sheet1!B:B,Sheet1!A:A) -> BLRSBMRFMSAPP1a | H41: 100.112.2.40 | I41: =_xlfn.XLOOKUP(H41,Sheet1!B:B,Sheet1!A:A) -> #N/A | J41: NAT_SUB 916 | K41: 100.112.3.40 | L41: =_xlfn.XLOOKUP(K41,Sheet1!B:B,Sheet1!A:A) -> #N/A | M41: 866 UAT-WEBJAP | N41: 100.112.4.40 | O41: =_xlfn.XLOOKUP(N41,Sheet1!B:B,Sheet1!A:A) -> #N/A | P41: 865 UAT-WEB-I | Q41: 100.112.5.40 | R41: =_xlfn.XLOOKUP(Q41,Sheet1!B:B,Sheet1!A:A) -> SuiteCRM_WEB_VIP | S41: 872 AD_Prod | T41: 100.112.6.40 | U41: =_xlfn.XLOOKUP(T41,Sheet1!B:B,Sheet1!A:A) -> LB Clustering self IP(floating) | V41: 912 UAT_APP2 | W41: 100.112.7.40 | X41: =_xlfn.XLOOKUP(W41,Sheet1!B:B,Sheet1!A:A) -> #N/A | Y41: 908 VDI-DB | Z41: 100.112.9.40 | AA41: =_xlfn.XLOOKUP(Z41,Sheet1!B:B,Sheet1!A:A) -> #N/A | AB41: 909 VDI | AC41: 100.112.10.40 | AD41: =_xlfn.XLOOKUP(AC41,Sheet1!B:B,Sheet1!A:A) -> #N/A | AE41: 670 New_APP | AF41: 100.112.12.40 | AG41: =_xlfn.XLOOKUP(AF41,Sheet1!B:B,Sheet1!A:A) -> #N/A | AI41: 100.112.26.40 | AJ41: =_xlfn.XLOOKUP(AI41,Sheet1!B:B,Sheet1!A:A) -> #N/A | AL41: 100.112.27.40 | AM41: =_xlfn.XLOOKUP(AL41,Sheet1!B:B,Sheet1!A:A) -> #N/A | AN41: 917 DSD | AO41: 100.112.28.40 | AP41: =_xlfn.XLOOKUP(AO41,Sheet1!B:B,Sheet1!A:A) -> #N/A
B42: 100.112.0.41 | C42: =_xlfn.XLOOKUP(B42,Sheet1!B:B,Sheet1!A:A) -> #N/A | E42: 100.112.1.41 | F42: =_xlfn.XLOOKUP(E42,Sheet1!B:B,Sheet1!A:A) -> BLRSBMRFMSAPP1b | H42: 100.112.2.41 | I42: =_xlfn.XLOOKUP(H42,Sheet1!B:B,Sheet1!A:A) -> #N/A | J42: NAT_SUB 916 | K42: 100.112.3.41 | L42: =_xlfn.XLOOKUP(K42,Sheet1!B:B,Sheet1!A:A) -> #N/A | M42: 866 UAT-WEBJAP | N42: 100.112.4.41 | O42: =_xlfn.XLOOKUP(N42,Sheet1!B:B,Sheet1!A:A) -> #N/A | P42: 865 UAT-WEB-I | Q42: 100.112.5.41 | R42: =_xlfn.XLOOKUP(Q42,Sheet1!B:B,Sheet1!A:A) -> NACHUAT_443_DR | S42: 872 AD_Prod | T42: 100.112.6.41 | U42: =_xlfn.XLOOKUP(T42,Sheet1!B:B,Sheet1!A:A) -> BNG-SBM-PRO-SW01 | V42: 912 UAT_APP2 | W42: 100.112.7.41 | X42: =_xlfn.XLOOKUP(W42,Sheet1!B:B,Sheet1!A:A) -> #N/A | Y42: 908 VDI-DB | Z42: 100.112.9.41 | AA42: =_xlfn.XLOOKUP(Z42,Sheet1!B:B,Sheet1!A:A) -> #N/A | AB42: 909 VDI | AC42: 100.112.10.41 | AD42: =_xlfn.XLOOKUP(AC42,Sheet1!B:B,Sheet1!A:A) -> #N/A | AE42: 670 New_APP | AF42: 100.112.12.41 | AG42: =_xlfn.XLOOKUP(AF42,Sheet1!B:B,Sheet1!A:A) -> #N/A | AI42: 100.112.26.41 | AJ42: =_xlfn.XLOOKUP(AI42,Sheet1!B:B,Sheet1!A:A) -> #N/A | AL42: 100.112.27.41 | AM42: =_xlfn.XLOOKUP(AL42,Sheet1!B:B,Sheet1!A:A) -> #N/A | AN42: 917 DSD | AO42: 100.112.28.41 | AP42: =_xlfn.XLOOKUP(AO42,Sheet1!B:B,Sheet1!A:A) -> #N/A
B43: 100.112.0.42 | C43: =_xlfn.XLOOKUP(B43,Sheet1!B:B,Sheet1!A:A) -> #N/A | E43: 100.112.1.42 | F43: =_xlfn.XLOOKUP(E43,Sheet1!B:B,Sheet1!A:A) -> BLRSBMRFMSAPP2a | H43: 100.112.2.42 | I43: =_xlfn.XLOOKUP(H43,Sheet1!B:B,Sheet1!A:A) -> #N/A | J43: NAT_SUB 916 | K43: 100.112.3.42 | L43: =_xlfn.XLOOKUP(K43,Sheet1!B:B,Sheet1!A:A) -> #N/A | M43: 866 UAT-WEBJAP | N43: 100.112.4.42 | O43: =_xlfn.XLOOKUP(N43,Sheet1!B:B,Sheet1!A:A) -> #N/A | P43: 865 UAT-WEB-I | Q43: 100.112.5.42 | R43: =_xlfn.XLOOKUP(Q43,Sheet1!B:B,Sheet1!A:A) -> Prayojan_WEB_UAT_VS | S43: 872 AD_Prod | T43: 100.112.6.42 | U43: =_xlfn.XLOOKUP(T43,Sheet1!B:B,Sheet1!A:A) -> BLRSBMPROSW02 | V43: 912 UAT_APP2 | W43: 100.112.7.42 | X43: =_xlfn.XLOOKUP(W43,Sheet1!B:B,Sheet1!A:A) -> #N/A | Y43: 908 VDI-DB | Z43: 100.112.9.42 | AA43: =_xlfn.XLOOKUP(Z43,Sheet1!B:B,Sheet1!A:A) -> #N/A | AB43: 909 VDI | AC43: 100.112.10.42 | AD43: =_xlfn.XLOOKUP(AC43,Sheet1!B:B,Sheet1!A:A) -> #N/A | AE43: 670 New_APP | AF43: 100.112.12.42 | AG43: =_xlfn.XLOOKUP(AF43,Sheet1!B:B,Sheet1!A:A) -> #N/A | AI43: 100.112.26.42 | AJ43: =_xlfn.XLOOKUP(AI43,Sheet1!B:B,Sheet1!A:A) -> #N/A | AL43: 100.112.27.42 | AM43: =_xlfn.XLOOKUP(AL43,Sheet1!B:B,Sheet1!A:A) -> #N/A | AN43: 917 DSD | AO43: 100.112.28.42 | AP43: =_xlfn.XLOOKUP(AO43,Sheet1!B:B,Sheet1!A:A) -> #N/A
B44: 100.112.0.43 | C44: =_xlfn.XLOOKUP(B44,Sheet1!B:B,Sheet1!A:A) -> #N/A | E44: 100.112.1.43 | F44: =_xlfn.XLOOKUP(E44,Sheet1!B:B,Sheet1!A:A) -> BLRSBMRFMSAPP2b | H44: 100.112.2.43 | I44: =_xlfn.XLOOKUP(H44,Sheet1!B:B,Sheet1!A:A) -> #N/A | J44: NAT_SUB 916 | K44: 100.112.3.43 | L44: =_xlfn.XLOOKUP(K44,Sheet1!B:B,Sheet1!A:A) -> #N/A | M44: 866 UAT-WEBJAP | N44: 100.112.4.43 | O44: =_xlfn.XLOOKUP(N44,Sheet1!B:B,Sheet1!A:A) -> #N/A | P44: 865 UAT-WEB-I | Q44: 100.112.5.43 | R44: =_xlfn.XLOOKUP(Q44,Sheet1!B:B,Sheet1!A:A) -> #N/A | S44: 872 AD_Prod | T44: 100.112.6.43 | U44: =_xlfn.XLOOKUP(T44,Sheet1!B:B,Sheet1!A:A) -> BLRSBMCC01 | V44: 912 UAT_APP2 | W44: 100.112.7.43 | X44: =_xlfn.XLOOKUP(W44,Sheet1!B:B,Sheet1!A:A) -> #N/A | Y44: 908 VDI-DB | Z44: 100.112.9.43 | AA44: =_xlfn.XLOOKUP(Z44,Sheet1!B:B,Sheet1!A:A) -> #N/A | AB44: 909 VDI | AC44: 100.112.10.43 | AD44: =_xlfn.XLOOKUP(AC44,Sheet1!B:B,Sheet1!A:A) -> #N/A | AE44: 670 New_APP | AF44: 100.112.12.43 | AG44: =_xlfn.XLOOKUP(AF44,Sheet1!B:B,Sheet1!A:A) -> #N/A | AI44: 100.112.26.43 | AJ44: =_xlfn.XLOOKUP(AI44,Sheet1!B:B,Sheet1!A:A) -> #N/A | AL44: 100.112.27.43 | AM44: =_xlfn.XLOOKUP(AL44,Sheet1!B:B,Sheet1!A:A) -> #N/A | AN44: 917 DSD | AO44: 100.112.28.43 | AP44: =_xlfn.XLOOKUP(AO44,Sheet1!B:B,Sheet1!A:A) -> #N/A
...

Sheet DC
A1: VLAN | B1: IP Address | C1: Hostname | D1: VLAN | E1: IP Address | F1: Hostname | G1: VLAN | H1: IP Address | I1: Hostname | J1: VLAN | K1: IP Address | L1: Hostname | M1: VLAN | N1: IP Address | O1: Hostname | P1: VLAN | Q1: IP Address | R1: Hostname | S1: VLAN | T1: IP Address | U1: Hostname | V1: VLAN | W1: IP Address | X1: Hostname | Y1: VLAN | Z1: IP Address | AA1: Hostname | AB1: VLAN | AC1: IP Address | AD1: Hostname
A2: Service Console 850 | B2: 100.121.16.1 | C2: =_xlfn.XLOOKUP(B2,Sheet1!B:B,Sheet1!A:A) -> vlan 850 | D2: Web-1 857 | E2: 100.121.17.1 | F2: =_xlfn.XLOOKUP(E2,Sheet1!B:B,Sheet1!A:A) -> vlan 857 | H2: 100.121.18.1 | I2: =_xlfn.XLOOKUP(H2,Sheet1!B:B,Sheet1!A:A) -> #N/A | J2: VDI_APP 847 | K2: 100.121.19.1 | L2: =_xlfn.XLOOKUP(K2,Sheet1!B:B,Sheet1!A:A) -> #N/A | M2: VDI_DHCP 891 | N2: 100.121.20.1 | O2: =_xlfn.XLOOKUP(N2,Sheet1!B:B,Sheet1!A:A) -> #N/A | Q2: 100.121.21.1 | R2: =_xlfn.XLOOKUP(Q2,Sheet1!B:B,Sheet1!A:A) -> #N/A | S2: APP2 901 | T2: 100.121.23.1 | U2: =_xlfn.XLOOKUP(T2,Sheet1!B:B,Sheet1!A:A) -> vlan 901 | V2: Proxy_to_Int | W2: 100.121.25.1 | X2: =_xlfn.XLOOKUP(W2,Sheet1!B:B,Sheet1!A:A) -> #N/A | Y2: DSD 905 | Z2: 100.121.28.1 | AA2: =_xlfn.XLOOKUP(Z2,Sheet1!B:B,Sheet1!A:A) -> DC_ASA Firewall1 | AB2: NAT_SUB 908 | AC2: 100.121.29.1 | AD2: =_xlfn.XLOOKUP(AC2,Sheet1!B:B,Sheet1!A:A) -> #N/A
A3: Service Console 850 | B3: 100.121.16.2 | C3: =_xlfn.XLOOKUP(B3,Sheet1!B:B,Sheet1!A:A) -> vlan 850_standby | D3: Web-1 857 | E3: 100.121.17.2 | F3: =_xlfn.XLOOKUP(E3,Sheet1!B:B,Sheet1!A:A) -> vlan 857_standby | H3: 100.121.18.2 | I3: =_xlfn.XLOOKUP(H3,Sheet1!B:B,Sheet1!A:A) -> #N/A | J3: VDI_APP 847 | K3: 100.121.19.2 | L3: =_xlfn.XLOOKUP(K3,Sheet1!B:B,Sheet1!A:A) -> MUMSBMVDIHCS01 | M3: VDI_DHCP 891 | N3: 100.121.20.2 | O3: =_xlfn.XLOOKUP(N3,Sheet1!B:B,Sheet1!A:A) -> #N/A | Q3: 100.121.21.2 | R3: =_xlfn.XLOOKUP(Q3,Sheet1!B:B,Sheet1!A:A) -> #N/A | S3: APP2 901 | T3: 100.121.23.2 | U3: =_xlfn.XLOOKUP(T3,Sheet1!B:B,Sheet1!A:A) -> vlan 901_standby | V3: Proxy_to_Int | W3: 100.121.25.2 | X3: =_xlfn.XLOOKUP(W3,Sheet1!B:B,Sheet1!A:A) -> #N/A | Y3: DSD 905 | Z3: 100.121.28.2 | AA3: =_xlfn.XLOOKUP(Z3,Sheet1!B:B,Sheet1!A:A) -> DC_ASA Firewall2 | AB3: NAT_SUB 908 | AC3: 100.121.29.2 | AD3: =_xlfn.XLOOKUP(AC3,Sheet1!B:B,Sheet1!A:A) -> #N/A
A4: Service Console 850 | B4: 100.121.16.3 | C4: =_xlfn.XLOOKUP(B4,Sheet1!B:B,Sheet1!A:A) -> MUMSBMOLVM01 | D4: Web-1 857 | E4: 100.121.17.3 | F4: =_xlfn.XLOOKUP(E4,Sheet1!B:B,Sheet1!A:A) -> #N/A | H4: 100.121.18.3 | I4: =_xlfn.XLOOKUP(H4,Sheet1!B:B,Sheet1!A:A) -> #N/A | J4: VDI_APP 847 | K4: 100.121.19.3 | L4: =_xlfn.XLOOKUP(K4,Sheet1!B:B,Sheet1!A:A) -> MUMSBMVDIDEM01 | M4: VDI_DHCP 891 | N4: 100.121.20.3 | O4: =_xlfn.XLOOKUP(N4,Sheet1!B:B,Sheet1!A:A) -> #N/A | Q4: 100.121.21.3 | R4: =_xlfn.XLOOKUP(Q4,Sheet1!B:B,Sheet1!A:A) -> #N/A | S4: APP2 901 | T4: 100.121.23.3 | U4: =_xlfn.XLOOKUP(T4,Sheet1!B:B,Sheet1!A:A) -> MUMSBMCLFMAP2 | V4: Proxy_to_Int | W4: 100.121.25.3 | X4: =_xlfn.XLOOKUP(W4,Sheet1!B:B,Sheet1!A:A) -> #N/A | Y4: DSD 905 | Z4: 100.121.28.3 | AA4: =_xlfn.XLOOKUP(Z4,Sheet1!B:B,Sheet1!A:A) -> MUMSBMFORTIMGR | AB4: NAT_SUB 908 | AC4: 100.121.29.3 | AD4: =_xlfn.XLOOKUP(AC4,Sheet1!B:B,Sheet1!A:A) -> #N/A
A5: Service Console 850 | B5: 100.121.16.4 | C5: =_xlfn.XLOOKUP(B5,Sheet1!B:B,Sheet1!A:A) -> MUMSBMVCM01 | D5: Web-1 857 | E5: 100.121.17.4 | F5: =_xlfn.XLOOKUP(E5,Sheet1!B:B,Sheet1!A:A) -> #N/A | H5: 100.121.18.4 | I5: =_xlfn.XLOOKUP(H5,Sheet1!B:B,Sheet1!A:A) -> #N/A | J5: VDI_APP 847 | K5: 100.121.19.4 | L5: =_xlfn.XLOOKUP(K5,Sheet1!B:B,Sheet1!A:A) -> MUMSBMVDICC01 | M5: VDI_DHCP 891 | N5: 100.121.20.4 | O5: =_xlfn.XLOOKUP(N5,Sheet1!B:B,Sheet1!A:A) -> #N/A | Q5: 100.121.21.4 | R5: =_xlfn.XLOOKUP(Q5,Sheet1!B:B,Sheet1!A:A) -> #N/A | S5: APP2 901 | T5: 100.121.23.4 | U5: =_xlfn.XLOOKUP(T5,Sheet1!B:B,Sheet1!A:A) -> MUMSBMCLFPAP1 | V5: Proxy_to_Int | W5: 100.121.25.4 | X5: MUMSBMNSPROXY1 | Y5: DSD 905 | Z5: 100.121.28.4 | AA5: =_xlfn.XLOOKUP(Z5,Sheet1!B:B,Sheet1!A:A) -> #N/A | AB5: NAT_SUB 908 | AC5: 100.121.29.4 | AD5: =_xlfn.XLOOKUP(AC5,Sheet1!B:B,Sheet1!A:A) -> #N/A
A6: Service Console 850 | B6: 100.121.16.5 | C6: =_xlfn.XLOOKUP(B6,Sheet1!B:B,Sheet1!A:A) -> MUMSBMVDIVSCA01 | D6: Web-1 857 | E6: 100.121.17.5 | F6: =_xlfn.XLOOKUP(E6,Sheet1!B:B,Sheet1!A:A) -> #N/A | H6: 100.121.18.5 | I6: =_xlfn.XLOOKUP(H6,Sheet1!B:B,Sheet1!A:A) -> #N/A | J6: VDI_APP 847 | K6: 100.121.19.5 | L6: =_xlfn.XLOOKUP(K6,Sheet1!B:B,Sheet1!A:A) -> MUMSBMVDILB01 | M6: VDI_DHCP 891 | N6: 100.121.20.5 | O6: =_xlfn.XLOOKUP(N6,Sheet1!B:B,Sheet1!A:A) -> #N/A | Q6: 100.121.21.5 | R6: =_xlfn.XLOOKUP(Q6,Sheet1!B:B,Sheet1!A:A) -> #N/A | S6: APP2 901 | T6: 100.121.23.5 | U6: =_xlfn.XLOOKUP(T6,Sheet1!B:B,Sheet1!A:A) -> MUMSBMCLFPAP2 | V6: Proxy_to_Int | W6: 100.121.25.5 | X6: =_xlfn.XLOOKUP(W6,Sheet1!B:B,Sheet1!A:A) -> #N/A | Y6: DSD 905 | Z6: 100.121.28.5 | AA6: =_xlfn.XLOOKUP(Z6,Sheet1!B:B,Sheet1!A:A) -> #N/A | AB6: NAT_SUB 908 | AC6: 100.121.29.5 | AD6: =_xlfn.XLOOKUP(AC6,Sheet1!B:B,Sheet1!A:A) -> #N/A
A7: Service Console 850 | B7: 100.121.16.6 | C7: =_xlfn.XLOOKUP(B7,Sheet1!B:B,Sheet1!A:A) -> mumsbmesx001 | D7: Web-1 857 | E7: 100.121.17.6 | F7: =_xlfn.XLOOKUP(E7,Sheet1!B:B,Sheet1!A:A) -> SBMCOREWEB_443_VS | H7: 100.121.18.6 | I7: =_xlfn.XLOOKUP(H7,Sheet1!B:B,Sheet1!A:A) -> #N/A | J7: VDI_APP 847 | K7: 100.121.19.6 | L7: =_xlfn.XLOOKUP(K7,Sheet1!B:B,Sheet1!A:A) -> #N/A | M7: VDI_DHCP 891 | N7: 100.121.20.6 | O7: =_xlfn.XLOOKUP(N7,Sheet1!B:B,Sheet1!A:A) -> #N/A | Q7: 100.121.21.6 | R7: =_xlfn.XLOOKUP(Q7,Sheet1!B:B,Sheet1!A:A) -> #N/A | S7: APP2 901 | T7: 100.121.23.6 | U7: =_xlfn.XLOOKUP(T7,Sheet1!B:B,Sheet1!A:A) -> MUMSBMCLCMSAP1 | V7: Proxy_to_Int | W7: 100.121.25.6 | X7: =_xlfn.XLOOKUP(W7,Sheet1!B:B,Sheet1!A:A) -> #N/A | Y7: DSD 905 | Z7: 100.121.28.6 | AA7: =_xlfn.XLOOKUP(Z7,Sheet1!B:B,Sheet1!A:A) -> #N/A | AB7: NAT_SUB 908 | AC7: 100.121.29.6 | AD7: =_xlfn.XLOOKUP(AC7,Sheet1!B:B,Sheet1!A:A) -> #N/A
A8: Service Console 850 | B8: 100.121.16.7 | C8: =_xlfn.XLOOKUP(B8,Sheet1!B:B,Sheet1!A:A) -> mumsbmesx002 | D8: Web-1 857 | E8: 100.121.17.93 | F8: =_xlfn.XLOOKUP(E8,Sheet1!B:B,Sheet1!A:A) -> MUMSBMESBWEB03 | H8: 100.121.18.7 | I8: =_xlfn.XLOOKUP(H8,Sheet1!B:B,Sheet1!A:A) -> #N/A | J8: VDI_APP 847 | K8: 100.121.19.7 | L8: =_xlfn.XLOOKUP(K8,Sheet1!B:B,Sheet1!A:A) -> #N/A | M8: VDI_DHCP 891 | N8: 100.121.20.7 | O8: =_xlfn.XLOOKUP(N8,Sheet1!B:B,Sheet1!A:A) -> #N/A | Q8: 100.121.21.7 | R8: =_xlfn.XLOOKUP(Q8,Sheet1!B:B,Sheet1!A:A) -> #N/A | S8: APP2 901 | T8: 100.121.23.7 | U8: =_xlfn.XLOOKUP(T8,Sheet1!B:B,Sheet1!A:A) -> MUMSBMCLCMSAP2 | V8: Proxy_to_Int | W8: 100.121.25.7 | X8: Virtual IP of Proxy | Y8: DSD 905 | Z8: 100.121.28.7 | AA8: =_xlfn.XLOOKUP(Z8,Sheet1!B:B,Sheet1!A:A) -> #N/A | AB8: NAT_SUB 908 | AC8: 100.121.29.7 | AD8: =_xlfn.XLOOKUP(AC8,Sheet1!B:B,Sheet1!A:A) -> #N/A
A9: Service Console 850 | B9: 100.121.16.8 | C9: =_xlfn.XLOOKUP(B9,Sheet1!B:B,Sheet1!A:A) -> mumsbmesx003 | D9: Web-1 857 | E9: 100.121.17.8 | F9: =_xlfn.XLOOKUP(E9,Sheet1!B:B,Sheet1!A:A) -> #N/A | H9: 100.121.18.8 | I9: =_xlfn.XLOOKUP(H9,Sheet1!B:B,Sheet1!A:A) -> #N/A | J9: VDI_APP 847 | K9: 100.121.19.8 | L9: =_xlfn.XLOOKUP(K9,Sheet1!B:B,Sheet1!A:A) -> #N/A | M9: VDI_DHCP 891 | N9: 100.121.20.8 | O9: =_xlfn.XLOOKUP(N9,Sheet1!B:B,Sheet1!A:A) -> #N/A | Q9: 100.121.21.8 | R9: =_xlfn.XLOOKUP(Q9,Sheet1!B:B,Sheet1!A:A) -> #N/A | S9: APP2 901 | T9: 100.121.23.8 | U9: =_xlfn.XLOOKUP(T9,Sheet1!B:B,Sheet1!A:A) -> MUMSBMWEBNEW | V9: Proxy_to_Int | W9: 100.121.25.8 | X9: =_xlfn.XLOOKUP(W9,Sheet1!B:B,Sheet1!A:A) -> #N/A | Y9: DSD 905 | Z9: 100.121.28.8 | AA9: =_xlfn.XLOOKUP(Z9,Sheet1!B:B,Sheet1!A:A) -> #N/A | AB9: NAT_SUB 908 | AC9: 100.121.29.8 | AD9: =_xlfn.XLOOKUP(AC9,Sheet1!B:B,Sheet1!A:A) -> #N/A
